Workbook

Sheet nas
A1: fun park
A3: التاريخ
A5: الايراد | C5: ل ل | D5: $$
B6: اراكيل | D6: =C6/90000 -> 0
B7: مشروبات | D7: =C7/90000 -> 0
B8: كريب | D8: =C8/90000 -> 0
B9: العاب | D9: =C9/90000 -> 0
B10: مختلف | D10: =C10/90000 -> 0
B11: الاجمالي | C11: =SUM(C6:C10) -> 0 | D11: =SUM(D6:D10) -> 0
A12: المصاريف | C12: ل ل | D12: $ | E12: تصفيه
A13: اراكيل | B13: معسل | D13: =C13/90000 -> 0 | E13: =IF(C13<>0,0,1) -> 1
B14: فحم | D14: =C14/90000 -> 0 | E14: =IF(C14<>0,0,1) -> 1
B15: نرابيج و لوازم | D15: =C15/90000 -> 0 | E15: =IF(C15<>0,0,1) -> 1
A16: عصائر | B16: فواكهة | D16: =C16/90000 -> 0 | E16: =IF(C16<>0,0,1) -> 1
B17: عسل | D17: =C17/90000 -> 0 | E17: =IF(C17<>0,0,1) -> 1
B18: نسلة | D18: =C18/90000 -> 0 | E18: =IF(C18<>0,0,1) -> 1
B19: شوكولا | D19: =C19/90000 -> 0 | E19: =IF(C19<>0,0,1) -> 1
B20: حليب | D20: =C20/90000 -> 0 | E20: =IF(C20<>0,0,1) -> 1
B21: مشروبات غازية | D21: =C21/90000 -> 0 | E21: =IF(C21<>0,0,1) -> 1
B22: نيسكافيه و كابتشينو | D22: =C22/90000 -> 0 | E22: =IF(C22<>0,0,1) -> 1
B23: قهوة مكنة | D23: =C23/90000 -> 0 | E23: =IF(C23<>0,0,1) -> 1
B24: لوازم أخرى | D24: =C24/90000 -> 0 | E24: =IF(C24<>0,0,1) -> 1
A25: لوازم | B25: كبيايات | D25: =C25/90000 -> 0 | E25: =IF(C25<>0,0,1) -> 1
B26: محارم | D26: =C26/90000 -> 0 | E26: =IF(C26<>0,0,1) -> 1
B27: مواد تنظيف | D27: =C27/90000 -> 0 | E27: =IF(C27<>0,0,1) -> 1
B28: مختلف | D28: =C28/90000 -> 0 | E28: =IF(C28<>0,0,1) -> 1
B29: مازوت | D29: =C29/90000 -> 0 | E29: =IF(C29<>0,0,1) -> 1
B30: صيانة | D30: =C30/90000 -> 0 | E30: =IF(C30<>0,0,1) -> 1
B31: اقتناء أصول | D31: =C31/90000 -> 0 | E31: =IF(C31<>0,0,1) -> 1
B32: سلف موظفين | D32: =C32/90000 -> 0 | E32: =IF(C32<>0,0,1) -> 1
B33: بنزين | D33: =C33/90000 -> 0 | E33: =IF(C33<>0,0,1) -> 1
B34: نقل | D34: =C34/90000 -> 0 | E34: =IF(C34<>0,0,1) -> 1
B35: رواتب | D35: =C35/90000 -> 0 | E35: =IF(C35<>0,0,1) -> 1
A37: اجمالي المصاريف | C37: =SUM(C13:C35) -> 0 | D37: =SUM(D13:D35) -> 0
A38: الرصيد السابق | D38: 1360
A40: الرصيد الحالي | C40: =(C38+C11)-C37 -> 0 | D40: =D38 -> 1360
B42: الرصيد $ | C42: =D40+(C40/90000) -> 1360

Sheet الرئيسية
D1: fun park
D3: جدول متابعة عن شهر آذار 2025
D5: الايام
C8: 1 | D8: 2 | E8: 3 | F8: 4 | G8: 5 | H8: 6 | I8: 7 | J8: 8 | K8: 9 | L8: 10 | M8: 11 | N8: 12 | O8: 13 | P8: 14 | Q8: 15 | R8: 16
C9: 17 | D9: 18 | E9: 19 | F9: 20 | G9: 21 | H9: 22 | I9: 23 | J9: 24 | K9: 25 | L9: 26 | M9: 27 | N9: 28 | O9: 29 | P9: 30 | Q9: 31
C11: مجموع الايام | G11: المجموع العام | K11: دراسة

Sheet 1
A1: fun park | D1: الصفحة الرئيسية
A3: التاريخ
A5: الايراد | C5: ل ل | D5: $$ | E5: عدد
B6: اراكيل | C6: 7150000 | D6: =C6/90000 -> 79.444444 | E6: 26
B7: مشروبات | C7: 17740000 | D7: =C7/90000 -> 197.11111 | E7: =E11-E6-E8-E9-E10 -> 114
B8: كريب | C8: 4720000 | D8: =C8/90000 -> 52.444444 | E8: 15
B9: العاب | C9: 6300000 | D9: =C9/90000 -> 70 | E9: 30
B10: مختلف | C10: 150000 | D10: =C10/90000 -> 1.6666667 | E10: 1
B11: الاجمالي | C11: =SUM(C6:C10) -> 36060000 | D11: =SUM(D6:D10) -> 400.66667 | E11: 186 | G11: =36060000-C11 -> 0
A12: المصاريف | C12: ل ل | D12: $ | E12: تصفيه
A13: اراكيل | B13: معسل | D13: =C13/90000 -> 0 | E13: =IF(C13<>0,0,1) -> 1
B14: فحم | D14: =C14/90000 -> 0 | E14: =IF(C14<>0,0,1) -> 1
B15: نرابيج و لوازم | C15: 200000 | D15: =C15/90000 -> 2.2222222 | E15: =IF(C15<>0,0,1) -> 0
A16: عصائر | B16: فواكهة | C16: 250000 | D16: =C16/90000 -> 2.7777778 | E16: =IF(C16<>0,0,1) -> 0
B17: عسل | D17: =C17/90000 -> 0 | E17: =IF(C17<>0,0,1) -> 1
B18: نسلة | D18: =C18/90000 -> 0 | E18: =IF(C18<>0,0,1) -> 1
B19: شوكولا | D19: =C19/90000 -> 0 | E19: =IF(C19<>0,0,1) -> 1
B20: حليب | D20: =C20/90000 -> 0 | E20: =IF(C20<>0,0,1) -> 1
B21: مشروبات غازية | D21: =C21/90000 -> 0 | E21: =IF(C21<>0,0,1) -> 1
B22: نيسكافيه و كابتشينو | D22: =C22/90000 -> 0 | E22: =IF(C22<>0,0,1) -> 1
B23: قهوة مكنة | D23: =C23/90000 -> 0 | E23: =IF(C23<>0,0,1) -> 1
B24: لوازم أخرى | D24: =C24/90000 -> 0 | E24: =IF(C24<>0,0,1) -> 1
A25: لوازم | B25: كبيايات | D25: =C25/90000 -> 0 | E25: =IF(C25<>0,0,1) -> 1
B26: محارم | D26: =C26/90000 -> 0 | E26: =IF(C26<>0,0,1) -> 1
B27: مواد تنظيف | D27: =C27/90000 -> 0 | E27: =IF(C27<>0,0,1) -> 1
B28: مختلف | C28: 2700000 | D28: =C28/90000 -> 30 | E28: =IF(C28<>0,0,1) -> 0
B29: مازوت | D29: =C29/90000 -> 0 | E29: =IF(C29<>0,0,1) -> 1
B30: صيانة | C30: 350000 | D30: =C30/90000 -> 3.8888889 | E30: =IF(C30<>0,0,1) -> 0
B31: اقتناء أصول | D31: =C31/90000 -> 0 | E31: =IF(C31<>0,0,1) -> 1
B32: سلف موظفين | C32: 750000 | D32: =C32/90000 -> 8.3333333 | E32: =IF(C32<>0,0,1) -> 0
B33: بنزين | D33: =C33/90000 -> 0 | E33: =IF(C33<>0,0,1) -> 1
B34: نقل | C34: 200000 | D34: =C34/90000 -> 2.2222222 | E34: =IF(C34<>0,0,1) -> 0
B35: رواتب | C35: 256620000 | D35: =C35/90000 -> 2851.3333 | E35: =IF(C35<>0,0,1) -> 0
A37: اجمالي المصاريف | C37: =SUM(C13:C35) -> 261070000 | D37: =SUM(D13:D35) -> 2900.7778
A38: الرصيد السابق | D38: 35632.943
A40: الرصيد الحالي | C40: =(C38+C11)-C37 -> -225010000 | D40: =D38 -> 35632.943
B42: الرصيد $ | C42: =D40+(C40/90000) -> 33132.832
A43: ملاحظات

Sheet 2
A1: fun park | D1: الصفحة الرئيسية
A3: التاريخ
A5: الايراد | C5: ل ل | D5: $$ | E5: عدد
B6: اراكيل | C6: 6860000 | D6: =C6/90000 -> 76.222222 | E6: 24
B7: مشروبات | C7: 23780000 | D7: =C7/90000 -> 264.22222 | E7: =E11-E6-E8-E9-E10 -> 132
B8: كريب | C8: =1570000+700000 -> 2270000 | D8: =C8/90000 -> 25.222222 | E8: 7
B9: العاب | C9: 9900000 | D9: =C9/90000 -> 110 | E9: 51
B10: مختلف | C10: 1160000 | D10: =C10/90000 -> 12.888889 | E10: 8
B11: الاجمالي | C11: =SUM(C6:C10) -> 43970000 | D11: =SUM(D6:D10) -> 488.55556 | E11: 222 | G11: =43970000-C11 -> 0
A12: المصاريف | C12: ل ل | D12: $ | E12: تصفيه
A13: اراكيل | B13: معسل | C13: =51*90000 -> 4590000 | D13: =C13/90000 -> 51 | E13: =IF(C13<>0,0,1) -> 0
B14: فحم | D14: =C14/90000 -> 0 | E14: =IF(C14<>0,0,1) -> 1
B15: نرابيج و لوازم | D15: =C15/90000 -> 0 | E15: =IF(C15<>0,0,1) -> 1
A16: عصائر | B16: فواكهة | C16: 1600000 | D16: =C16/90000 -> 17.777778 | E16: =IF(C16<>0,0,1) -> 0
B17: عسل | D17: =C17/90000 -> 0 | E17: =IF(C17<>0,0,1) -> 1
B18: نسلة | D18: =C18/90000 -> 0 | E18: =IF(C18<>0,0,1) -> 1
B19: شوكولا | C19: =46*90000 -> 4140000 | D19: =C19/90000 -> 46 | E19: =IF(C19<>0,0,1) -> 0
B20: حليب | D20: =C20/90000 -> 0 | E20: =IF(C20<>0,0,1) -> 1
B21: مشروبات غازية | D21: =C21/90000 -> 0 | E21: =IF(C21<>0,0,1) -> 1
B22: نيسكافيه و كابتشينو | D22: =C22/90000 -> 0 | E22: =IF(C22<>0,0,1) -> 1
B23: قهوة مكنة | D23: =C23/90000 -> 0 | E23: =IF(C23<>0,0,1) -> 1
B24: لوازم أخرى | D24: =C24/90000 -> 0 | E24: =IF(C24<>0,0,1) -> 1
A25: لوازم | B25: كبيايات | D25: =C25/90000 -> 0 | E25: =IF(C25<>0,0,1) -> 1
B26: محارم | D26: =C26/90000 -> 0 | E26: =IF(C26<>0,0,1) -> 1
B27: مواد تنظيف | D27: =C27/90000 -> 0 | E27: =IF(C27<>0,0,1) -> 1
B28: مختلف | D28: =C28/90000 -> 0 | E28: =IF(C28<>0,0,1) -> 1
B29: مازوت | D29: =C29/90000 -> 0 | E29: =IF(C29<>0,0,1) -> 1
B30: صيانة | C30: 2700000 | D30: =C30/90000 -> 30 | E30: =IF(C30<>0,0,1) -> 0
B31: اقتناء أصول | D31: =C31/90000 -> 0 | E31: =IF(C31<>0,0,1) -> 1
B32: سلف موظفين | C32: =1800000+200000 -> 2000000 | D32: =C32/90000 -> 22.222222 | E32: =IF(C32<>0,0,1) -> 0
B33: بنزين | D33: =C33/90000 -> 0 | E33: =IF(C33<>0,0,1) -> 1
B34: نقل | D34: =C34/90000 -> 0 | E34: =IF(C34<>0,0,1) -> 1
B35: رواتب | D35: =C35/90000 -> 0 | E35: =IF(C35<>0,0,1) -> 1
A37: اجمالي المصاريف | C37: =SUM(C13:C35) -> 15030000 | D37: =SUM(D13:D35) -> 167
A38: الرصيد السابق | D38: ='1'!C42 -> 33132.832
A40: الرصيد الحالي | C40: =(C38+C11)-C37 -> 28940000 | D40: =D38 -> 33132.832
B42: الرصيد $ | C42: =D40+(C40/90000) -> 33454.387
A43: ملاحظات

Sheet 3
A1: fun park | D1: الصفحة الرئيسية
A3: التاريخ
A5: الايراد | C5: ل ل | D5: $$ | E5: عدد
B6: اراكيل | C6: 8130000 | D6: =C6/90000 -> 90.333333 | E6: 28
B7: مشروبات | C7: 27200000 | D7: =C7/90000 -> 302.22222 | E7: =E11-E6-E8-E9-E10 -> 157
B8: كريب | C8: 5090000 | D8: =C8/90000 -> 56.555556 | E8: 16
B9: العاب | C9: 11750000 | D9: =C9/90000 -> 130.55556 | E9: 56
B10: مختلف | D10: =C10/90000 -> 0
B11: الاجمالي | C11: =SUM(C6:C10) -> 52170000 | D11: =SUM(D6:D10) -> 579.66667 | E11: 257 | G11: =52170000-C11 -> 0
A12: المصاريف | C12: ل ل | D12: $ | E12: تصفيه
A13: اراكيل | B13: معسل | D13: =C13/90000 -> 0 | E13: =IF(C13<>0,0,1) -> 1
B14: فحم | D14: =C14/90000 -> 0 | E14: =IF(C14<>0,0,1) -> 1
B15: نرابيج و لوازم | D15: =C15/90000 -> 0 | E15: =IF(C15<>0,0,1) -> 1
A16: عصائر | B16: فواكهة | D16: =C16/90000 -> 0 | E16: =IF(C16<>0,0,1) -> 1
B17: عسل | D17: =C17/90000 -> 0 | E17: =IF(C17<>0,0,1) -> 1
B18: نسلة | D18: =C18/90000 -> 0 | E18: =IF(C18<>0,0,1) -> 1
B19: شوكولا | D19: =C19/90000 -> 0 | E19: =IF(C19<>0,0,1) -> 1
B20: حليب | D20: =C20/90000 -> 0 | E20: =IF(C20<>0,0,1) -> 1
B21: مشروبات غازية | D21: =C21/90000 -> 0 | E21: =IF(C21<>0,0,1) -> 1
B22: نيسكافيه و كابتشينو | D22: =C22/90000 -> 0 | E22: =IF(C22<>0,0,1) -> 1
B23: قهوة مكنة | D23: =C23/90000 -> 0 | E23: =IF(C23<>0,0,1) -> 1
B24: لوازم أخرى | D24: =C24/90000 -> 0 | E24: =IF(C24<>0,0,1) -> 1
A25: لوازم | B25: كبيايات | D25: =C25/90000 -> 0 | E25: =IF(C25<>0,0,1) -> 1
B26: محارم | D26: =C26/90000 -> 0 | E26: =IF(C26<>0,0,1) -> 1
B27: مواد تنظيف | D27: =C27/90000 -> 0 | E27: =IF(C27<>0,0,1) -> 1
B28: مختلف | C28: 80000 | D28: =C28/90000 -> 0.88888889 | E28: =IF(C28<>0,0,1) -> 0
B29: مازوت | D29: =C29/90000 -> 0 | E29: =IF(C29<>0,0,1) -> 1
B30: صيانة | D30: =C30/90000 -> 0 | E30: =IF(C30<>0,0,1) -> 1
B31: اقتناء أصول | D31: =C31/90000 -> 0 | E31: =IF(C31<>0,0,1) -> 1
B32: سلف موظفين | C32: 1360000 | D32: =C32/90000 -> 15.111111 | E32: =IF(C32<>0,0,1) -> 0
B33: بنزين | D33: =C33/90000 -> 0 | E33: =IF(C33<>0,0,1) -> 1
B34: نقل | C34: 200000 | D34: =C34/90000 -> 2.2222222 | E34: =IF(C34<>0,0,1) -> 0
B35: رواتب | C35: 500000 | D35: =C35/90000 -> 5.5555556 | E35: =IF(C35<>0,0,1) -> 0
A37: اجمالي المصاريف | C37: =SUM(C13:C35) -> 2140000 | D37: =SUM(D13:D35) -> 23.777778
A38: الرصيد السابق | D38: ='2'!C42 -> 33454.387
A40: الرصيد الحالي | C40: =(C38+C11)-C37 -> 50030000 | D40: =D38 -> 33454.387
B42: الرصيد $ | C42: =D40+(C40/90000) -> 34010.276
A43: ملاحظات

Sheet 4
A1: fun park | D1: الصفحة الرئيسية
A3: التاريخ
A5: الايراد | C5: ل ل | D5: $$ | E5: عدد
B6: اراكيل | C6: 7630000 | D6: =C6/90000 -> 84.777778 | E6: 26
B7: مشروبات | C7: 29680000 | D7: =C7/90000 -> 329.77778 | E7: =E11-E6-E8-E9-E10 -> 168
B8: كريب | C8: 4960000 | D8: =C8/90000 -> 55.111111 | E8: 15
B9: العاب | C9: 9650000 | D9: =C9/90000 -> 107.22222 | E9: 41
B10: مختلف | D10: =C10/90000 -> 0
B11: الاجمالي | C11: =SUM(C6:C10) -> 51920000 | D11: =SUM(D6:D10) -> 576.88889 | E11: 250 | G11: =51920000-C11 -> 0
A12: المصاريف | C12: ل ل | D12: $ | E12: تصفيه
A13: اراكيل | B13: معسل | D13: =C13/90000 -> 0 | E13: =IF(C13<>0,0,1) -> 1
B14: فحم | D14: =C14/90000 -> 0 | E14: =IF(C14<>0,0,1) -> 1
B15: نرابيج و لوازم | D15: =C15/90000 -> 0 | E15: =IF(C15<>0,0,1) -> 1
A16: عصائر | B16: فواكهة | C16: 1650000 | D16: =C16/90000 -> 18.333333 | E16: =IF(C16<>0,0,1) -> 0
B17: عسل | D17: =C17/90000 -> 0 | E17: =IF(C17<>0,0,1) -> 1
B18: نسلة | D18: =C18/90000 -> 0 | E18: =IF(C18<>0,0,1) -> 1
B19: شوكولا | D19: =C19/90000 -> 0 | E19: =IF(C19<>0,0,1) -> 1
B20: حليب | D20: =C20/90000 -> 0 | E20: =IF(C20<>0,0,1) -> 1
B21: مشروبات غازية | D21: =C21/90000 -> 0 | E21: =IF(C21<>0,0,1) -> 1
B22: نيسكافيه و كابتشينو | D22: =C22/90000 -> 0 | E22: =IF(C22<>0,0,1) -> 1
B23: قهوة مكنة | D23: =C23/90000 -> 0 | E23: =IF(C23<>0,0,1) -> 1
B24: لوازم أخرى | D24: =C24/90000 -> 0 | E24: =IF(C24<>0,0,1) -> 1
A25: لوازم | B25: كبيايات | D25: =C25/90000 -> 0 | E25: =IF(C25<>0,0,1) -> 1
B26: محارم | D26: =C26/90000 -> 0 | E26: =IF(C26<>0,0,1) -> 1
B27: مواد تنظيف | D27: =C27/90000 -> 0 | E27: =IF(C27<>0,0,1) -> 1
B28: مختلف | D28: =C28/90000 -> 0 | E28: =IF(C28<>0,0,1) -> 1
B29: مازوت | D29: =C29/90000 -> 0 | E29: =IF(C29<>0,0,1) -> 1
B30: صيانة | C30: =90*90000 -> 8100000 | D30: =C30/90000 -> 90 | E30: =IF(C30<>0,0,1) -> 0
B31: اقتناء أصول | D31: =C31/90000 -> 0 | E31: =IF(C31<>0,0,1) -> 1
B32: سلف موظفين | C32: 200000 | D32: =C32/90000 -> 2.2222222 | E32: =IF(C32<>0,0,1) -> 0
B33: بنزين | D33: =C33/90000 -> 0 | E33: =IF(C33<>0,0,1) -> 1
B34: نقل | C34: 200000 | D34: =C34/90000 -> 2.2222222 | E34: =IF(C34<>0,0,1) -> 0
B35: رواتب | D35: =C35/90000 -> 0 | E35: =IF(C35<>0,0,1) -> 1
A37: اجمالي المصاريف | C37: =SUM(C13:C35) -> 10150000 | D37: =SUM(D13:D35) -> 112.77778
A38: الرصيد السابق | D38: ='3'!C42 -> 34010.276
A40: الرصيد الحالي | C40: =(C38+C11)-C37 -> 41770000 | D40: =D38 -> 34010.276
B42: الرصيد $ | C42: =D40+(C40/90000) -> 34474.387
A43: ملاحظات

Sheet 5
A1: fun park | D1: الصفحة الرئيسية
A3: التاريخ
A5: الايراد | C5: ل ل | D5: $$ | E5: عدد
B6: اراكيل | C6: 7860000 | D6: =C6/90000 -> 87.333333 | E6: 27
B7: مشروبات | C7: 24360000 | D7: =C7/90000 -> 270.66667 | E7: =E11-E6-E8-E9-E10 -> 148
B8: كريب | C8: 3880000 | D8: =C8/90000 -> 43.111111 | E8: 12
B9: العاب | C9: 8950000 | D9: =C9/90000 -> 99.444444 | E9: 37
B10: مختلف | C10: 2470000 | D10: =C10/90000 -> 27.444444 | E10: 17
B11: الاجمالي | C11: =SUM(C6:C10) -> 47520000 | D11: =SUM(D6:D10) -> 528 | E11: 241 | G11: =47520000-C11 -> 0
A12: المصاريف | C12: ل ل | D12: $ | E12: تصفيه
A13: اراكيل | B13: معسل | D13: =C13/90000 -> 0 | E13: =IF(C13<>0,0,1) -> 1
B14: فحم | D14: =C14/90000 -> 0 | E14: =IF(C14<>0,0,1) -> 1
B15: نرابيج و لوازم | D15: =C15/90000 -> 0 | E15: =IF(C15<>0,0,1) -> 1
A16: عصائر | B16: فواكهة | D16: =C16/90000 -> 0 | E16: =IF(C16<>0,0,1) -> 1
B17: عسل | D17: =C17/90000 -> 0 | E17: =IF(C17<>0,0,1) -> 1
B18: نسلة | D18: =C18/90000 -> 0 | E18: =IF(C18<>0,0,1) -> 1
B19: شوكولا | C19: =29*90000 -> 2610000 | D19: =C19/90000 -> 29 | E19: =IF(C19<>0,0,1) -> 0
B20: حليب | D20: =C20/90000 -> 0 | E20: =IF(C20<>0,0,1) -> 1
B21: مشروبات غازية | D21: =C21/90000 -> 0 | E21: =IF(C21<>0,0,1) -> 1
B22: نيسكافيه و كابتشينو | D22: =C22/90000 -> 0 | E22: =IF(C22<>0,0,1) -> 1
B23: قهوة مكنة | D23: =C23/90000 -> 0 | E23: =IF(C23<>0,0,1) -> 1
B24: لوازم أخرى | D24: =C24/90000 -> 0 | E24: =IF(C24<>0,0,1) -> 1
A25: لوازم | B25: كبيايات | D25: =C25/90000 -> 0 | E25: =IF(C25<>0,0,1) -> 1
B26: محارم | D26: =C26/90000 -> 0 | E26: =IF(C26<>0,0,1) -> 1
B27: مواد تنظيف | D27: =C27/90000 -> 0 | E27: =IF(C27<>0,0,1) -> 1
B28: مختلف | D28: =C28/90000 -> 0 | E28: =IF(C28<>0,0,1) -> 1
B29: مازوت | D29: =C29/90000 -> 0 | E29: =IF(C29<>0,0,1) -> 1
B30: صيانة | D30: =C30/90000 -> 0 | E30: =IF(C30<>0,0,1) -> 1
B31: اقتناء أصول | D31: =C31/90000 -> 0 | E31: =IF(C31<>0,0,1) -> 1
B32: سلف موظفين | C32: 350000 | D32: =C32/90000 -> 3.8888889 | E32: =IF(C32<>0,0,1) -> 0
B33: بنزين | D33: =C33/90000 -> 0 | E33: =IF(C33<>0,0,1) -> 1
B34: نقل | C34: 200000 | D34: =C34/90000 -> 2.2222222 | E34: =IF(C34<>0,0,1) -> 0
B35: رواتب | D35: =C35/90000 -> 0 | E35: =IF(C35<>0,0,1) -> 1
A37: اجمالي المصاريف | C37: =SUM(C13:C35) -> 3160000 | D37: =SUM(D13:D35) -> 35.111111
A38: الرصيد السابق | D38: ='4'!C42 -> 34474.387
A40: الرصيد الحالي | C40: =(C38+C11)-C37 -> 44360000 | D40: =D38 -> 34474.387
B42: الرصيد $ | C42: =D40+(C40/90000) -> 34967.276
A43: ملاحظات

Sheet  6
A1: fun park | D1: الصفحة الرئيسية
A3: التاريخ
A5: الايراد | C5: ل ل | D5: $$ | E5: عدد
B6: اراكيل | C6: 1200000 | D6: =C6/90000 -> 13.333333 | E6: 4
B7: مشروبات | C7: 10440000 | D7: =C7/90000 -> 116 | E7: =E11-E6-E8-E9-E10 -> 41
B8: كريب | C8: 660000 | D8: =C8/90000 -> 7.3333333 | E8: 2
B9: العاب | C9: 2750000 | D9: =C9/90000 -> 30.555556 | E9: 11
B10: مختلف | D10: =C10/90000 -> 0
B11: الاجمالي | C11: =SUM(C6:C10) -> 15050000 | D11: =SUM(D6:D10) -> 167.22222 | E11: 58 | G11: =15050000-C11 -> 0
A12: المصاريف | C12: ل ل | D12: $ | E12: تصفيه
A13: اراكيل | B13: معسل | D13: =C13/90000 -> 0 | E13: =IF(C13<>0,0,1) -> 1
B14: فحم | D14: =C14/90000 -> 0 | E14: =IF(C14<>0,0,1) -> 1
B15: نرابيج و لوازم | C15: 400000 | D15: =C15/90000 -> 4.4444444 | E15: =IF(C15<>0,0,1) -> 0
A16: عصائر | B16: فواكهة | C16: 10000000 | D16: =C16/90000 -> 111.11111 | E16: =IF(C16<>0,0,1) -> 0
B17: عسل | D17: =C17/90000 -> 0 | E17: =IF(C17<>0,0,1) -> 1
B18: نسلة | D18: =C18/90000 -> 0 | E18: =IF(C18<>0,0,1) -> 1
B19: شوكولا | D19: =C19/90000 -> 0 | E19: =IF(C19<>0,0,1) -> 1
B20: حليب | D20: =C20/90000 -> 0 | E20: =IF(C20<>0,0,1) -> 1
B21: مشروبات غازية | C21: =159*90000 -> 14310000 | D21: =C21/90000 -> 159 | E21: =IF(C21<>0,0,1) -> 0
B22: نيسكافيه و كابتشينو | D22: =C22/90000 -> 0 | E22: =IF(C22<>0,0,1) -> 1
B23: قهوة مكنة | D23: =C23/90000 -> 0 | E23: =IF(C23<>0,0,1) -> 1
B24: لوازم أخرى | D24: =C24/90000 -> 0 | E24: =IF(C24<>0,0,1) -> 1
A25: لوازم | B25: كبيايات | D25: =C25/90000 -> 0 | E25: =IF(C25<>0,0,1) -> 1
B26: محارم | C26: =63*90000 -> 5670000 | D26: =C26/90000 -> 63 | E26: =IF(C26<>0,0,1) -> 0
B27: مواد تنظيف | C27: 2300000 | D27: =C27/90000 -> 25.555556 | E27: =IF(C27<>0,0,1) -> 0
B28: مختلف | D28: =C28/90000 -> 0 | E28: =IF(C28<>0,0,1) -> 1
B29: مازوت | D29: =C29/90000 -> 0 | E29: =IF(C29<>0,0,1) -> 1
B30: صيانة | C30: =45*90000 -> 4050000 | D30: =C30/90000 -> 45 | E30: =IF(C30<>0,0,1) -> 0
B31: اقتناء أصول | D31: =C31/90000 -> 0 | E31: =IF(C31<>0,0,1) -> 1
B32: سلف موظفين | C32: 280000 | D32: =C32/90000 -> 3.1111111 | E32: =IF(C32<>0,0,1) -> 0
B33: بنزين | D33: =C33/90000 -> 0 | E33: =IF(C33<>0,0,1) -> 1
B34: نقل | C34: 200000 | D34: =C34/90000 -> 2.2222222 | E34: =IF(C34<>0,0,1) -> 0
B35: رواتب | C35: 1800000 | D35: =C35/90000 -> 20 | E35: =IF(C35<>0,0,1) -> 0
A37: اجمالي المصاريف | C37: =SUM(C13:C35) -> 39010000 | D37: =SUM(D13:D35) -> 433.44444
A38: الرصيد السابق | D38: ='5'!C42 -> 34967.276
A40: الرصيد الحالي | C40: =(C38+C11)-C37 -> -23960000 | D40: =D38 -> 34967.276
B42: الرصيد $ | C42: =D40+(C40/90000) -> 34701.054
A43: ملاحظات

Sheet 7
A1: fun park | D1: الصفحة الرئيسية
A3: التاريخ
A5: الايراد | C5: ل ل | D5: $$ | E5: عدد
B6: اراكيل | C6: 600000 | D6: =C6/90000 -> 6.6666667 | E6: 2
B7: مشروبات | C7: 5070000 | D7: =C7/90000 -> 56.333333 | E7: =E11-E6-E8-E9-E10 -> 19
B8: كريب | C8: 1900000 | D8: =C8/90000 -> 21.111111 | E8: 6
B9: العاب | C9: 750000 | D9: =C9/90000 -> 8.3333333 | E9: 3
B10: مختلف | D10: =C10/90000 -> 0
B11: الاجمالي | C11: =SUM(C6:C10) -> 8320000 | D11: =SUM(D6:D10) -> 92.444444 | E11: 30 | G11: =8320000-C11 -> 0
A12: المصاريف | C12: ل ل | D12: $ | E12: تصفيه
A13: اراكيل | B13: معسل | D13: =C13/90000 -> 0 | E13: =IF(C13<>0,0,1) -> 1
B14: فحم | D14: =C14/90000 -> 0 | E14: =IF(C14<>0,0,1) -> 1
B15: نرابيج و لوازم | D15: =C15/90000 -> 0 | E15: =IF(C15<>0,0,1) -> 1
A16: عصائر | B16: فواكهة | D16: =C16/90000 -> 0 | E16: =IF(C16<>0,0,1) -> 1
B17: عسل | C17: =145*90000 -> 13050000 | D17: =C17/90000 -> 145 | E17: =IF(C17<>0,0,1) -> 0
B18: نسلة | D18: =C18/90000 -> 0 | E18: =IF(C18<>0,0,1) -> 1
B19: شوكولا | D19: =C19/90000 -> 0 | E19: =IF(C19<>0,0,1) -> 1
B20: حليب | D20: =C20/90000 -> 0 | E20: =IF(C20<>0,0,1) -> 1
B21: مشروبات غازية | D21: =C21/90000 -> 0 | E21: =IF(C21<>0,0,1) -> 1
B22: نيسكافيه و كابتشينو | D22: =C22/90000 -> 0 | E22: =IF(C22<>0,0,1) -> 1
B23: قهوة مكنة | D23: =C23/90000 -> 0 | E23: =IF(C23<>0,0,1) -> 1
B24: لوازم أخرى | D24: =C24/90000 -> 0 | E24: =IF(C24<>0,0,1) -> 1
A25: لوازم | B25: كبيايات | D25: =C25/90000 -> 0 | E25: =IF(C25<>0,0,1) -> 1
B26: محارم | D26: =C26/90000 -> 0 | E26: =IF(C26<>0,0,1) -> 1
B27: مواد تنظيف | D27: =C27/90000 -> 0 | E27: =IF(C27<>0,0,1) -> 1
B28: مختلف | D28: =C28/90000 -> 0 | E28: =IF(C28<>0,0,1) -> 1
B29: مازوت | D29: =C29/90000 -> 0 | E29: =IF(C29<>0,0,1) -> 1
B30: صيانة | D30: =C30/90000 -> 0 | E30: =IF(C30<>0,0,1) -> 1
B31: اقتناء أصول | C31: =(1978+637)*90000 -> 235350000 | D31: =C31/90000 -> 2615 | E31: =IF(C31<>0,0,1) -> 0
B32: سلف موظفين | C32: 100000 | D32: =C32/90000 -> 1.1111111 | E32: =IF(C32<>0,0,1) -> 0
B33: بنزين | D33: =C33/90000 -> 0 | E33: =IF(C33<>0,0,1) -> 1
B34: نقل | C34: 200000 | D34: =C34/90000 -> 2.2222222 | E34: =IF(C34<>0,0,1) -> 0
B35: رواتب | D35: =C35/90000 -> 0 | E35: =IF(C35<>0,0,1) -> 1
A37: اجمالي المصاريف | C37: =SUM(C13:C35) -> 248700000 | D37: =SUM(D13:D35) -> 2763.3333
A38: الرصيد السابق | D38: =' 6'!C42 -> 34701.054
A40: الرصيد الحالي | C40: =(C38+C11)-C37 -> -240380000 | D40: =D38 -> 34701.054
B42: الرصيد $ | C42: =D40+(C40/90000) -> 32030.165
A43: ملاحظات
A44: ثمن سقف + مواد للشلال

Sheet 8
A1: fun park | D1: الصفحة الرئيسية
A3: التاريخ
A5: الايراد | C5: ل ل | D5: $$ | E5: عدد
B6: اراكيل | C6: 2100000 | D6: =C6/90000 -> 23.333333 | E6: 7
B7: مشروبات | C7: 14120000 | D7: =C7/90000 -> 156.88889 | E7: =E11-E6-E8-E9-E10 -> 63
B8: كريب | C8: 1610000 | D8: =C8/90000 -> 17.888889 | E8: 5
B9: العاب | C9: 4750000 | D9: =C9/90000 -> 52.777778 | E9: 22
B10: مختلف | C10: 150000 | D10: =C10/90000 -> 1.6666667 | E10: 1
B11: الاجمالي | C11: =SUM(C6:C10) -> 22730000 | D11: =SUM(D6:D10) -> 252.55556 | E11: 98 | G11: =22730000-C11 -> 0
A12: المصاريف | C12: ل ل | D12: $ | E12: تصفيه
A13: اراكيل | B13: معسل | D13: =C13/90000 -> 0 | E13: =IF(C13<>0,0,1) -> 1
B14: فحم | D14: =C14/90000 -> 0 | E14: =IF(C14<>0,0,1) -> 1
B15: نرابيج و لوازم | D15: =C15/90000 -> 0 | E15: =IF(C15<>0,0,1) -> 1
A16: عصائر | B16: فواكهة | D16: =C16/90000 -> 0 | E16: =IF(C16<>0,0,1) -> 1
B17: عسل | D17: =C17/90000 -> 0 | E17: =IF(C17<>0,0,1) -> 1
B18: نسلة | D18: =C18/90000 -> 0 | E18: =IF(C18<>0,0,1) -> 1
B19: شوكولا | D19: =C19/90000 -> 0 | E19: =IF(C19<>0,0,1) -> 1
B20: حليب | D20: =C20/90000 -> 0 | E20: =IF(C20<>0,0,1) -> 1
B21: مشروبات غازية | D21: =C21/90000 -> 0 | E21: =IF(C21<>0,0,1) -> 1
B22: نيسكافيه و كابتشينو | D22: =C22/90000 -> 0 | E22: =IF(C22<>0,0,1) -> 1
B23: قهوة مكنة | D23: =C23/90000 -> 0 | E23: =IF(C23<>0,0,1) -> 1
B24: لوازم أخرى | D24: =C24/90000 -> 0 | E24: =IF(C24<>0,0,1) -> 1
A25: لوازم | B25: كبيايات | D25: =C25/90000 -> 0 | E25: =IF(C25<>0,0,1) -> 1
B26: محارم | D26: =C26/90000 -> 0 | E26: =IF(C26<>0,0,1) -> 1
B27: مواد تنظيف | D27: =C27/90000 -> 0 | E27: =IF(C27<>0,0,1) -> 1
B28: مختلف | C28: =104*90000 -> 9360000 | D28: =C28/90000 -> 104 | E28: =IF(C28<>0,0,1) -> 0
B29: مازوت | D29: =C29/90000 -> 0 | E29: =IF(C29<>0,0,1) -> 1
B30: صيانة | D30: =C30/90000 -> 0 | E30: =IF(C30<>0,0,1) -> 1
B31: اقتناء أصول | C31: =5500*90000 -> 495000000 | D31: =C31/90000 -> 5500 | E31: =IF(C31<>0,0,1) -> 0
B32: سلف موظفين | D32: =C32/90000 -> 0 | E32: =IF(C32<>0,0,1) -> 1
B33: بنزين | D33: =C33/90000 -> 0 | E33: =IF(C33<>0,0,1) -> 1
B34: نقل | C34: 200000 | D34: =C34/90000 -> 2.2222222 | E34: =IF(C34<>0,0,1) -> 0
B35: رواتب | D35: =C35/90000 -> 0 | E35: =IF(C35<>0,0,1) -> 1
A37: اجمالي المصاريف | C37: =SUM(C13:C35) -> 504560000 | D37: =SUM(D13:D35) -> 5606.2222
A38: الرصيد السابق | D38: ='7'!C42 -> 32030.165
A40: الرصيد الحالي | C40: =(C38+C11)-C37 -> -481830000 | D40: =D38 -> 32030.165
B42: الرصيد $ | C42: =D40+(C40/90000) -> 26676.499
A43: ملاحظات
A44: ثمن عفش
A45: غاز

Sheet 9
A1: fun park | D1: الصفحة الرئيسية
A3: التاريخ
A5: الايراد | C5: ل ل | D5: $$ | E5: عدد
B6: اراكيل | C6: 900000 | D6: =C6/90000 -> 10 | E6: 3
B7: مشروبات | C7: 1650000 | D7: =C7/90000 -> 18.333333 | E7: =E11-E6-E8-E9-E10 -> 12
B8: كريب | D8: =C8/90000 -> 0
B9: العاب | C9: 750000 | D9: =C9/90000 -> 8.3333333 | E9: 3
B10: مختلف | D10: =C10/90000 -> 0
B11: الاجمالي | C11: =SUM(C6:C10) -> 3300000 | D11: =SUM(D6:D10) -> 36.666667 | E11: 18 | G11: =3300000-C11 -> 0
A12: المصاريف | C12: ل ل | D12: $ | E12: تصفيه
A13: اراكيل | B13: معسل | D13: =C13/90000 -> 0 | E13: =IF(C13<>0,0,1) -> 1
B14: فحم | D14: =C14/90000 -> 0 | E14: =IF(C14<>0,0,1) -> 1
B15: نرابيج و لوازم | D15: =C15/90000 -> 0 | E15: =IF(C15<>0,0,1) -> 1
A16: عصائر | B16: فواكهة | D16: =C16/90000 -> 0 | E16: =IF(C16<>0,0,1) -> 1
B17: عسل | D17: =C17/90000 -> 0 | E17: =IF(C17<>0,0,1) -> 1
B18: نسلة | D18: =C18/90000 -> 0 | E18: =IF(C18<>0,0,1) -> 1
B19: شوكولا | D19: =C19/90000 -> 0 | E19: =IF(C19<>0,0,1) -> 1
B20: حليب | D20: =C20/90000 -> 0 | E20: =IF(C20<>0,0,1) -> 1
B21: مشروبات غازية | D21: =C21/90000 -> 0 | E21: =IF(C21<>0,0,1) -> 1
B22: نيسكافيه و كابتشينو | D22: =C22/90000 -> 0 | E22: =IF(C22<>0,0,1) -> 1
B23: قهوة مكنة | D23: =C23/90000 -> 0 | E23: =IF(C23<>0,0,1) -> 1
B24: لوازم أخرى | C24: 1900000 | D24: =C24/90000 -> 21.111111 | E24: =IF(C24<>0,0,1) -> 0
A25: لوازم | B25: كبيايات | D25: =C25/90000 -> 0 | E25: =IF(C25<>0,0,1) -> 1
B26: محارم | D26: =C26/90000 -> 0 | E26: =IF(C26<>0,0,1) -> 1
B27: مواد تنظيف | D27: =C27/90000 -> 0 | E27: =IF(C27<>0,0,1) -> 1
B28: مختلف | D28: =C28/90000 -> 0 | E28: =IF(C28<>0,0,1) -> 1
B29: مازوت | D29: =C29/90000 -> 0 | E29: =IF(C29<>0,0,1) -> 1
B30: صيانة | D30: =C30/90000 -> 0 | E30: =IF(C30<>0,0,1) -> 1
B31: اقتناء أصول | C31: 9000000 | D31: =C31/90000 -> 100 | E31: =IF(C31<>0,0,1) -> 0
B32: سلف موظفين | D32: =C32/90000 -> 0 | E32: =IF(C32<>0,0,1) -> 1
B33: بنزين | D33: =C33/90000 -> 0 | E33: =IF(C33<>0,0,1) -> 1
B34: نقل | C34: 200000 | D34: =C34/90000 -> 2.2222222 | E34: =IF(C34<>0,0,1) -> 0
B35: رواتب | D35: =C35/90000 -> 0 | E35: =IF(C35<>0,0,1) -> 1
A37: اجمالي المصاريف | C37: =SUM(C13:C35) -> 11100000 | D37: =SUM(D13:D35) -> 123.33333
A38: الرصيد السابق | D38: ='8'!C42 -> 26676.499
A40: الرصيد الحالي | C40: =(C38+C11)-C37 -> -7800000 | D40: ='8'!C42 -> 26676.499
B42: الرصيد $ | C42: =D40+(C40/90000) -> 26589.832
A43: ملاحظات

Sheet 10
A1: fun park | D1: الصفحة الرئيسية
A3: التاريخ
A5: الايراد | C5: ل ل | D5: $$ | E5: عدد
B6: اراكيل | C6: 5100000 | D6: =C6/90000 -> 56.666667 | E6: 17
B7: مشروبات | C7: 17830000 | D7: =C7/90000 -> 198.11111 | E7: =E11-E6-E8-E9-E10 -> 83
B8: كريب | C8: 1250000 | D8: =C8/90000 -> 13.888889 | E8: 4
B9: العاب | C9: 8500000 | D9: =C9/90000 -> 94.444444 | E9: 37
B10: مختلف | C10: 840000 | D10: =C10/90000 -> 9.3333333 | E10: 6
B11: الاجمالي | C11: =SUM(C6:C10) -> 33520000 | D11: =SUM(D6:D10) -> 372.44444 | E11: 147 | G11: =33520000-C11 -> 0
A12: المصاريف | C12: ل ل | D12: $ | E12: تصفيه
A13: اراكيل | B13: معسل | C13: =47*90000 -> 4230000 | D13: =C13/90000 -> 47 | E13: =IF(C13<>0,0,1) -> 0
B14: فحم | D14: =C14/90000 -> 0 | E14: =IF(C14<>0,0,1) -> 1
B15: نرابيج و لوازم | D15: =C15/90000 -> 0 | E15: =IF(C15<>0,0,1) -> 1
A16: عصائر | B16: فواكهة | C16: 500000 | D16: =C16/90000 -> 5.5555556 | E16: =IF(C16<>0,0,1) -> 0
B17: عسل | D17: =C17/90000 -> 0 | E17: =IF(C17<>0,0,1) -> 1
B18: نسلة | D18: =C18/90000 -> 0 | E18: =IF(C18<>0,0,1) -> 1
B19: شوكولا | C19: =55*90000 -> 4950000 | D19: =C19/90000 -> 55 | E19: =IF(C19<>0,0,1) -> 0
B20: حليب | D20: =C20/90000 -> 0 | E20: =IF(C20<>0,0,1) -> 1
B21: مشروبات غازية | D21: =C21/90000 -> 0 | E21: =IF(C21<>0,0,1) -> 1
B22: نيسكافيه و كابتشينو | D22: =C22/90000 -> 0 | E22: =IF(C22<>0,0,1) -> 1
B23: قهوة مكنة | D23: =C23/90000 -> 0 | E23: =IF(C23<>0,0,1) -> 1
B24: لوازم أخرى | C24: 1800000 | D24: =C24/90000 -> 20 | E24: =IF(C24<>0,0,1) -> 0
A25: لوازم | B25: كبيايات | D25: =C25/90000 -> 0 | E25: =IF(C25<>0,0,1) -> 1
B26: محارم | D26: =C26/90000 -> 0 | E26: =IF(C26<>0,0,1) -> 1
B27: مواد تنظيف | D27: =C27/90000 -> 0 | E27: =IF(C27<>0,0,1) -> 1
B28: مختلف | D28: =C28/90000 -> 0 | E28: =IF(C28<>0,0,1) -> 1
B29: مازوت | D29: =C29/90000 -> 0 | E29: =IF(C29<>0,0,1) -> 1
B30: صيانة | C30: 1350000 | D30: =C30/90000 -> 15 | E30: =IF(C30<>0,0,1) -> 0
B31: اقتناء أصول | C31: =400*90000 -> 36000000 | D31: =C31/90000 -> 400 | E31: =IF(C31<>0,0,1) -> 0
B32: سلف موظفين | C32: 1470000 | D32: =C32/90000 -> 16.333333 | E32: =IF(C32<>0,0,1) -> 0
B33: بنزين | D33: =C33/90000 -> 0 | E33: =IF(C33<>0,0,1) -> 1
B34: نقل | C34: 200000 | D34: =C34/90000 -> 2.2222222 | E34: =IF(C34<>0,0,1) -> 0
B35: رواتب | D35: =C35/90000 -> 0 | E35: =IF(C35<>0,0,1) -> 1
A37: اجمالي المصاريف | C37: =SUM(C13:C35) -> 50500000 | D37: =SUM(D13:D35) -> 561.11111
A38: الرصيد السابق | D38: ='9'!C42 -> 26589.832
A40: الرصيد الحالي | C40: =(C38+C11)-C37 -> -16980000 | D40: =D38 -> 26589.832
B42: الرصيد $ | C42: =D40+(C40/90000) -> 26401.165
A43: ملاحظات
A44: اجار تركيب السقف

Sheet 11
A1: fun park | D1: الصفحة الرئيسية
A3: التاريخ
A5: الايراد | C5: ل ل | D5: $$ | E5: عدد
B6: اراكيل | C6: 5350000 | D6: =C6/90000 -> 59.444444 | E6: 18
B7: مشروبات | C7: 16160000 | D7: =C7/90000 -> 179.55556 | E7: =E11-E6-E8-E9-E10 -> 100
B8: كريب | C8: 4890000 | D8: =C8/90000 -> 54.333333 | E8: 15
B9: العاب | C9: 5700000 | D9: =C9/90000 -> 63.333333 | E9: 27
B10: مختلف | C10: 730000 | D10: =C10/90000 -> 8.1111111 | E10: 5
B11: الاجمالي | C11: =SUM(C6:C10) -> 32830000 | D11: =SUM(D6:D10) -> 364.77778 | E11: 165 | G11: =32830000-C11 -> 0
A12: المصاريف | C12: ل ل | D12: $ | E12: تصفيه
A13: اراكيل | B13: معسل | D13: =C13/90000 -> 0 | E13: =IF(C13<>0,0,1) -> 1
B14: فحم | D14: =C14/90000 -> 0 | E14: =IF(C14<>0,0,1) -> 1
B15: نرابيج و لوازم | D15: =C15/90000 -> 0 | E15: =IF(C15<>0,0,1) -> 1
A16: عصائر | B16: فواكهة | D16: =C16/90000 -> 0 | E16: =IF(C16<>0,0,1) -> 1
B17: عسل | D17: =C17/90000 -> 0 | E17: =IF(C17<>0,0,1) -> 1
B18: نسلة | D18: =C18/90000 -> 0 | E18: =IF(C18<>0,0,1) -> 1
B19: شوكولا | D19: =C19/90000 -> 0 | E19: =IF(C19<>0,0,1) -> 1
B20: حليب | D20: =C20/90000 -> 0 | E20: =IF(C20<>0,0,1) -> 1
B21: مشروبات غازية | D21: =C21/90000 -> 0 | E21: =IF(C21<>0,0,1) -> 1
B22: نيسكافيه و كابتشينو | D22: =C22/90000 -> 0 | E22: =IF(C22<>0,0,1) -> 1
B23: قهوة مكنة | D23: =C23/90000 -> 0 | E23: =IF(C23<>0,0,1) -> 1
B24: لوازم أخرى | D24: =C24/90000 -> 0 | E24: =IF(C24<>0,0,1) -> 1
A25: لوازم | B25: كبيايات | D25: =C25/90000 -> 0 | E25: =IF(C25<>0,0,1) -> 1
B26: محارم | D26: =C26/90000 -> 0 | E26: =IF(C26<>0,0,1) -> 1
B27: مواد تنظيف | D27: =C27/90000 -> 0 | E27: =IF(C27<>0,0,1) -> 1
B28: مختلف | D28: =C28/90000 -> 0 | E28: =IF(C28<>0,0,1) -> 1
B29: مازوت | D29: =C29/90000 -> 0 | E29: =IF(C29<>0,0,1) -> 1
B30: صيانة | D30: =C30/90000 -> 0 | E30: =IF(C30<>0,0,1) -> 1
B31: اقتناء أصول | D31: =C31/90000 -> 0 | E31: =IF(C31<>0,0,1) -> 1
B32: سلف موظفين | C32: 100000 | D32: =C32/90000 -> 1.1111111 | E32: =IF(C32<>0,0,1) -> 0
B33: بنزين | D33: =C33/90000 -> 0 | E33: =IF(C33<>0,0,1) -> 1
B34: نقل | C34: 200000 | D34: =C34/90000 -> 2.2222222 | E34: =IF(C34<>0,0,1) -> 0
B35: رواتب | D35: =C35/90000 -> 0 | E35: =IF(C35<>0,0,1) -> 1
A37: اجمالي المصاريف | C37: =SUM(C13:C35) -> 300000 | D37: =SUM(D13:D35) -> 3.3333333
A38: الرصيد السابق | D38: ='10'!C42 -> 26401.165
A40: الرصيد الحالي | C40: =(C38+C11)-C37 -> 32530000 | D40: =D38 -> 26401.165
B42: الرصيد $ | C42: =D40+(C40/90000) -> 26762.61
A43: ملاحظات

Sheet 12
A1: fun park | D1: الصفحة الرئيسية
A3: التاريخ
A5: الايراد | C5: ل ل | D5: $$ | E5: عدد
B6: اراكيل | C6: 2940000 | D6: =C6/90000 -> 32.666667 | E6: 10
B7: مشروبات | C7: 13780000 | D7: =C7/90000 -> 153.11111 | E7: =E11-E6-E8-E9-E10 -> 61
B8: كريب | C8: 2260000 | D8: =C8/90000 -> 25.111111 | E8: 7
B9: العاب | C9: 5550000 | D9: =C9/90000 -> 61.666667 | E9: 24
B10: مختلف | C10: 1180000 | D10: =C10/90000 -> 13.111111 | E10: 8
B11: الاجمالي | C11: =SUM(C6:C10) -> 25710000 | D11: =SUM(D6:D10) -> 285.66667 | E11: 110 | G11: =25710000-C11 -> 0
A12: المصاريف | C12: ل ل | D12: $ | E12: تصفيه
A13: اراكيل | B13: معسل | D13: =C13/90000 -> 0 | E13: =IF(C13<>0,0,1) -> 1
B14: فحم | D14: =C14/90000 -> 0 | E14: =IF(C14<>0,0,1) -> 1
B15: نرابيج و لوازم | D15: =C15/90000 -> 0 | E15: =IF(C15<>0,0,1) -> 1
A16: عصائر | B16: فواكهة | C16: 800000 | D16: =C16/90000 -> 8.8888889 | E16: =IF(C16<>0,0,1) -> 0
B17: عسل | D17: =C17/90000 -> 0 | E17: =IF(C17<>0,0,1) -> 1
B18: نسلة | D18: =C18/90000 -> 0 | E18: =IF(C18<>0,0,1) -> 1
B19: شوكولا | C19: 900000 | D19: =C19/90000 -> 10 | E19: =IF(C19<>0,0,1) -> 0
B20: حليب | D20: =C20/90000 -> 0 | E20: =IF(C20<>0,0,1) -> 1
B21: مشروبات غازية | D21: =C21/90000 -> 0 | E21: =IF(C21<>0,0,1) -> 1
B22: نيسكافيه و كابتشينو | D22: =C22/90000 -> 0 | E22: =IF(C22<>0,0,1) -> 1
B23: قهوة مكنة | D23: =C23/90000 -> 0 | E23: =IF(C23<>0,0,1) -> 1
B24: لوازم أخرى | D24: =C24/90000 -> 0 | E24: =IF(C24<>0,0,1) -> 1
A25: لوازم | B25: كبيايات | D25: =C25/90000 -> 0 | E25: =IF(C25<>0,0,1) -> 1
B26: محارم | D26: =C26/90000 -> 0 | E26: =IF(C26<>0,0,1) -> 1
B27: مواد تنظيف | D27: =C27/90000 -> 0 | E27: =IF(C27<>0,0,1) -> 1
B28: مختلف | C28: 670000 | D28: =C28/90000 -> 7.4444444 | E28: =IF(C28<>0,0,1) -> 0
B29: مازوت | D29: =C29/90000 -> 0 | E29: =IF(C29<>0,0,1) -> 1
B30: صيانة | C30: 900000 | D30: =C30/90000 -> 10 | E30: =IF(C30<>0,0,1) -> 0
B31: اقتناء أصول | C31: =80*90000 -> 7200000 | D31: =C31/90000 -> 80 | E31: =IF(C31<>0,0,1) -> 0
B32: سلف موظفين | C32: 1000000 | D32: =C32/90000 -> 11.111111 | E32: =IF(C32<>0,0,1) -> 0
B33: بنزين | D33: =C33/90000 -> 0 | E33: =IF(C33<>0,0,1) -> 1
B34: نقل | C34: 200000 | D34: =C34/90000 -> 2.2222222 | E34: =IF(C34<>0,0,1) -> 0
B35: رواتب | C35: =220*90000 -> 19800000 | D35: =C35/90000 -> 220 | E35: =IF(C35<>0,0,1) -> 0
A37: اجمالي المصاريف | C37: =SUM(C13:C35) -> 31470000 | D37: =SUM(D13:D35) -> 349.66667
A38: الرصيد السابق | D38: ='11'!C42 -> 26762.61
A40: الرصيد الحالي | C40: =(C38+C11)-C37 -> -5760000 | D40: =D38 -> 26762.61
B42: الرصيد $ | C42: =D40+(C40/90000) -> 26698.61
A43: ملاحظات
A44: راتب أبو حسام

Sheet 13
A1: fun park | D1: الصفحة الرئيسية
A3: التاريخ
A5: الايراد | C5: ل ل | D5: $$ | E5: عدد
B6: اراكيل | C6: 1500000 | D6: =C6/90000 -> 16.666667 | E6: 5
B7: مشروبات | C7: 4810000 | D7: =C7/90000 -> 53.444444 | E7: =E11-E6-E8-E9-E10 -> 33
B8: كريب | C8: 1790000 | D8: =C8/90000 -> 19.888889 | E8: 5
B9: العاب | C9: 2750000 | D9: =C9/90000 -> 30.555556 | E9: 11
B10: مختلف | C10: 150000 | D10: =C10/90000 -> 1.6666667 | E10: 1
B11: الاجمالي | C11: =SUM(C6:C10) -> 11000000 | D11: =SUM(D6:D10) -> 122.22222 | E11: 55 | G11: =11000000-C11 -> 0
A12: المصاريف | C12: ل ل | D12: $ | E12: تصفيه
A13: اراكيل | B13: معسل | D13: =C13/90000 -> 0 | E13: =IF(C13<>0,0,1) -> 1
B14: فحم | D14: =C14/90000 -> 0 | E14: =IF(C14<>0,0,1) -> 1
B15: نرابيج و لوازم | D15: =C15/90000 -> 0 | E15: =IF(C15<>0,0,1) -> 1
A16: عصائر | B16: فواكهة | C16: 2000000 | D16: =C16/90000 -> 22.222222 | E16: =IF(C16<>0,0,1) -> 0
B17: عسل | D17: =C17/90000 -> 0 | E17: =IF(C17<>0,0,1) -> 1
B18: نسلة | D18: =C18/90000 -> 0 | E18: =IF(C18<>0,0,1) -> 1
B19: شوكولا | D19: =C19/90000 -> 0 | E19: =IF(C19<>0,0,1) -> 1
B20: حليب | D20: =C20/90000 -> 0 | E20: =IF(C20<>0,0,1) -> 1
B21: مشروبات غازية | D21: =C21/90000 -> 0 | E21: =IF(C21<>0,0,1) -> 1
B22: نيسكافيه و كابتشينو | D22: =C22/90000 -> 0 | E22: =IF(C22<>0,0,1) -> 1
B23: قهوة مكنة | D23: =C23/90000 -> 0 | E23: =IF(C23<>0,0,1) -> 1
B24: لوازم أخرى | D24: =C24/90000 -> 0 | E24: =IF(C24<>0,0,1) -> 1
A25: لوازم | B25: كبيايات | D25: =C25/90000 -> 0 | E25: =IF(C25<>0,0,1) -> 1
B26: محارم | D26: =C26/90000 -> 0 | E26: =IF(C26<>0,0,1) -> 1
B27: مواد تنظيف | D27: =C27/90000 -> 0 | E27: =IF(C27<>0,0,1) -> 1
B28: مختلف | D28: =C28/90000 -> 0 | E28: =IF(C28<>0,0,1) -> 1
B29: مازوت | D29: =C29/90000 -> 0 | E29: =IF(C29<>0,0,1) -> 1
B30: صيانة | D30: =C30/90000 -> 0 | E30: =IF(C30<>0,0,1) -> 1
B31: اقتناء أصول | D31: =C31/90000 -> 0 | E31: =IF(C31<>0,0,1) -> 1
B32: سلف موظفين | D32: =C32/90000 -> 0 | E32: =IF(C32<>0,0,1) -> 1
B33: بنزين | D33: =C33/90000 -> 0 | E33: =IF(C33<>0,0,1) -> 1
B34: نقل | C34: 200000 | D34: =C34/90000 -> 2.2222222 | E34: =IF(C34<>0,0,1) -> 0
B35: رواتب | D35: =C35/90000 -> 0 | E35: =IF(C35<>0,0,1) -> 1
A37: اجمالي المصاريف | C37: =SUM(C13:C35) -> 2200000 | D37: =SUM(D13:D35) -> 24.444444
A38: الرصيد السابق | D38: ='12'!C42 -> 26698.61
A40: الرصيد الحالي | C40: =(C38+C11)-C37 -> 8800000 | D40: =D38 -> 26698.61
B42: الرصيد $ | C42: =D40+(C40/90000) -> 26796.387
A43: ملاحظات

Sheet 14
A1: fun park | D1: الصفحة الرئيسية
A3: التاريخ
A5: الايراد | C5: ل ل | D5: $$ | E5: عدد
B6: اراكيل | C6: 2100000 | D6: =C6/90000 -> 23.333333 | E6: 7
B7: مشروبات | C7: 4510000 | D7: =C7/90000 -> 50.111111 | E7: =E11-E6-E8-E9-E10 -> 25
B8: كريب | C8: 2850000 | D8: =C8/90000 -> 31.666667 | E8: 9
B9: العاب | C9: 3900000 | D9: =C9/90000 -> 43.333333 | E9: 18
B10: مختلف | D10: =C10/90000 -> 0
B11: الاجمالي | C11: =SUM(C6:C10) -> 13360000 | D11: =SUM(D6:D10) -> 148.44444 | E11: 59 | G11: =13360000-C11 -> 0
A12: المصاريف | C12: ل ل | D12: $ | E12: تصفيه
A13: اراكيل | B13: معسل | D13: =C13/90000 -> 0 | E13: =IF(C13<>0,0,1) -> 1
B14: فحم | D14: =C14/90000 -> 0 | E14: =IF(C14<>0,0,1) -> 1
B15: نرابيج و لوازم | D15: =C15/90000 -> 0 | E15: =IF(C15<>0,0,1) -> 1
A16: عصائر | B16: فواكهة | D16: =C16/90000 -> 0 | E16: =IF(C16<>0,0,1) -> 1
B17: عسل | D17: =C17/90000 -> 0 | E17: =IF(C17<>0,0,1) -> 1
B18: نسلة | D18: =C18/90000 -> 0 | E18: =IF(C18<>0,0,1) -> 1
B19: شوكولا | D19: =C19/90000 -> 0 | E19: =IF(C19<>0,0,1) -> 1
B20: حليب | D20: =C20/90000 -> 0 | E20: =IF(C20<>0,0,1) -> 1
B21: مشروبات غازية | D21: =C21/90000 -> 0 | E21: =IF(C21<>0,0,1) -> 1
B22: نيسكافيه و كابتشينو | D22: =C22/90000 -> 0 | E22: =IF(C22<>0,0,1) -> 1
B23: قهوة مكنة | D23: =C23/90000 -> 0 | E23: =IF(C23<>0,0,1) -> 1
B24: لوازم أخرى | C24: 550000 | D24: =C24/90000 -> 6.1111111 | E24: =IF(C24<>0,0,1) -> 0
A25: لوازم | B25: كبيايات | D25: =C25/90000 -> 0 | E25: =IF(C25<>0,0,1) -> 1
B26: محارم | D26: =C26/90000 -> 0 | E26: =IF(C26<>0,0,1) -> 1
B27: مواد تنظيف | C27: 900000 | D27: =C27/90000 -> 10 | E27: =IF(C27<>0,0,1) -> 0
B28: مختلف | D28: =C28/90000 -> 0 | E28: =IF(C28<>0,0,1) -> 1
B29: مازوت | D29: =C29/90000 -> 0 | E29: =IF(C29<>0,0,1) -> 1
B30: صيانة | C30: =24*90000 -> 2160000 | D30: =C30/90000 -> 24 | E30: =IF(C30<>0,0,1) -> 0
B31: اقتناء أصول | C31: =186*90000 -> 16740000 | D31: =C31/90000 -> 186 | E31: =IF(C31<>0,0,1) -> 0
B32: سلف موظفين | C32: 100000 | D32: =C32/90000 -> 1.1111111 | E32: =IF(C32<>0,0,1) -> 0
B33: بنزين | D33: =C33/90000 -> 0 | E33: =IF(C33<>0,0,1) -> 1
B34: نقل | C34: 200000 | D34: =C34/90000 -> 2.2222222 | E34: =IF(C34<>0,0,1) -> 0
B35: رواتب | D35: =C35/90000 -> 0 | E35: =IF(C35<>0,0,1) -> 1
A37: اجمالي المصاريف | C37: =SUM(C13:C35) -> 20650000 | D37: =SUM(D13:D35) -> 229.44444
A38: الرصيد السابق | D38: ='13'!C42 -> 26796.387
A40: الرصيد الحالي | C40: =(C38+C11)-C37 -> -7290000 | D40: =D38 -> 26796.387
B42: الرصيد $ | C42: =D40+(C40/90000) -> 26715.387
A43: ملاحظات
A44: انارة للسقف

Sheet 15
A1: fun park | D1: الصفحة الرئيسية
A3: التاريخ
A5: الايراد | C5: ل ل | D5: $$ | E5: عدد
B6: اراكيل | C6: 3300000 | D6: =C6/90000 -> 36.666667 | E6: 11
B7: مشروبات | C7: 10890000 | D7: =C7/90000 -> 121 | E7: =E11-E6-E8-E9-E10 -> 54
B8: كريب | C8: 1940000 | D8: =C8/90000 -> 21.555556 | E8: 6
B9: العاب | C9: 3250000 | D9: =C9/90000 -> 36.111111 | E9: 13
B10: مختلف | D10: =C10/90000 -> 0
B11: الاجمالي | C11: =SUM(C6:C10) -> 19380000 | D11: =SUM(D6:D10) -> 215.33333 | E11: 84 | G11: =19380000-C11 -> 0
A12: المصاريف | C12: ل ل | D12: $ | E12: تصفيه
A13: اراكيل | B13: معسل | D13: =C13/90000 -> 0 | E13: =IF(C13<>0,0,1) -> 1
B14: فحم | D14: =C14/90000 -> 0 | E14: =IF(C14<>0,0,1) -> 1
B15: نرابيج و لوازم | D15: =C15/90000 -> 0 | E15: =IF(C15<>0,0,1) -> 1
A16: عصائر | B16: فواكهة | C16: 400000 | D16: =C16/90000 -> 4.4444444 | E16: =IF(C16<>0,0,1) -> 0
B17: عسل | D17: =C17/90000 -> 0 | E17: =IF(C17<>0,0,1) -> 1
B18: نسلة | D18: =C18/90000 -> 0 | E18: =IF(C18<>0,0,1) -> 1
B19: شوكولا | D19: =C19/90000 -> 0 | E19: =IF(C19<>0,0,1) -> 1
B20: حليب | D20: =C20/90000 -> 0 | E20: =IF(C20<>0,0,1) -> 1
B21: مشروبات غازية | C21: 1620000 | D21: =C21/90000 -> 18 | E21: =IF(C21<>0,0,1) -> 0
B22: نيسكافيه و كابتشينو | D22: =C22/90000 -> 0 | E22: =IF(C22<>0,0,1) -> 1
B23: قهوة مكنة | D23: =C23/90000 -> 0 | E23: =IF(C23<>0,0,1) -> 1
B24: لوازم أخرى | D24: =C24/90000 -> 0 | E24: =IF(C24<>0,0,1) -> 1
A25: لوازم | B25: كبيايات | D25: =C25/90000 -> 0 | E25: =IF(C25<>0,0,1) -> 1
B26: محارم | D26: =C26/90000 -> 0 | E26: =IF(C26<>0,0,1) -> 1
B27: مواد تنظيف | D27: =C27/90000 -> 0 | E27: =IF(C27<>0,0,1) -> 1
B28: مختلف | D28: =C28/90000 -> 0 | E28: =IF(C28<>0,0,1) -> 1
B29: مازوت | D29: =C29/90000 -> 0 | E29: =IF(C29<>0,0,1) -> 1
B30: صيانة | D30: =C30/90000 -> 0 | E30: =IF(C30<>0,0,1) -> 1
B31: اقتناء أصول | D31: =C31/90000 -> 0 | E31: =IF(C31<>0,0,1) -> 1
B32: سلف موظفين | C32: 200000 | D32: =C32/90000 -> 2.2222222 | E32: =IF(C32<>0,0,1) -> 0
B33: بنزين | D33: =C33/90000 -> 0 | E33: =IF(C33<>0,0,1) -> 1
B34: نقل | C34: 200000 | D34: =C34/90000 -> 2.2222222 | E34: =IF(C34<>0,0,1) -> 0
B35: رواتب | D35: =C35/90000 -> 0 | E35: =IF(C35<>0,0,1) -> 1
A37: اجمالي المصاريف | C37: =SUM(C13:C35) -> 2420000 | D37: =SUM(D13:D35) -> 26.888889
A38: الرصيد السابق | D38: ='14'!C42 -> 26715.387
A40: الرصيد الحالي | C40: =(C38+C11)-C37 -> 16960000 | D40: =D38 -> 26715.387
B42: الرصيد $ | C42: =D40+(C40/90000) -> 26903.832
A43: ملاحظات

Sheet 16
A1: fun park | D1: الصفحة الرئيسية
A3: التاريخ
A5: الايراد | C5: ل ل | D5: $$ | E5: عدد
B6: اراكيل | C6: 3000000 | D6: =C6/90000 -> 33.333333 | E6: 10
B7: مشروبات | C7: 12110000 | D7: =C7/90000 -> 134.55556 | E7: =E11-E6-E8-E9-E10 -> 60
B8: كريب | C8: 4180000 | D8: =C8/90000 -> 46.444444 | E8: 13
B9: العاب | C9: 4400000 | D9: =C9/90000 -> 48.888889 | E9: 20
B10: مختلف | C10: 150000 | D10: =C10/90000 -> 1.6666667 | E10: 1
B11: الاجمالي | C11: =SUM(C6:C10) -> 23840000 | D11: =SUM(D6:D10) -> 264.88889 | E11: 104 | G11: =23840000-C11 -> 0
A12: المصاريف | C12: ل ل | D12: $ | E12: تصفيه
A13: اراكيل | B13: معسل | D13: =C13/90000 -> 0 | E13: =IF(C13<>0,0,1) -> 1
B14: فحم | D14: =C14/90000 -> 0 | E14: =IF(C14<>0,0,1) -> 1
B15: نرابيج و لوازم | D15: =C15/90000 -> 0 | E15: =IF(C15<>0,0,1) -> 1
A16: عصائر | B16: فواكهة | D16: =C16/90000 -> 0 | E16: =IF(C16<>0,0,1) -> 1
B17: عسل | C17: 1800000 | D17: =C17/90000 -> 20 | E17: =IF(C17<>0,0,1) -> 0
B18: نسلة | D18: =C18/90000 -> 0 | E18: =IF(C18<>0,0,1) -> 1
B19: شوكولا | D19: =C19/90000 -> 0 | E19: =IF(C19<>0,0,1) -> 1
B20: حليب | D20: =C20/90000 -> 0 | E20: =IF(C20<>0,0,1) -> 1
B21: مشروبات غازية | D21: =C21/90000 -> 0 | E21: =IF(C21<>0,0,1) -> 1
B22: نيسكافيه و كابتشينو | D22: =C22/90000 -> 0 | E22: =IF(C22<>0,0,1) -> 1
B23: قهوة مكنة | D23: =C23/90000 -> 0 | E23: =IF(C23<>0,0,1) -> 1
B24: لوازم أخرى | D24: =C24/90000 -> 0 | E24: =IF(C24<>0,0,1) -> 1
A25: لوازم | B25: كبيايات | D25: =C25/90000 -> 0 | E25: =IF(C25<>0,0,1) -> 1
B26: محارم | D26: =C26/90000 -> 0 | E26: =IF(C26<>0,0,1) -> 1
B27: مواد تنظيف | D27: =C27/90000 -> 0 | E27: =IF(C27<>0,0,1) -> 1
B28: مختلف | D28: =C28/90000 -> 0 | E28: =IF(C28<>0,0,1) -> 1
B29: مازوت | D29: =C29/90000 -> 0 | E29: =IF(C29<>0,0,1) -> 1
B30: صيانة | C30: 9000000 | D30: =C30/90000 -> 100 | E30: =IF(C30<>0,0,1) -> 0
B31: اقتناء أصول | C31: =220*90000 -> 19800000 | D31: =C31/90000 -> 220 | E31: =IF(C31<>0,0,1) -> 0
B32: سلف موظفين | C32: 400000 | D32: =C32/90000 -> 4.4444444 | E32: =IF(C32<>0,0,1) -> 0
B33: بنزين | D33: =C33/90000 -> 0 | E33: =IF(C33<>0,0,1) -> 1
B34: نقل | C34: 200000 | D34: =C34/90000 -> 2.2222222 | E34: =IF(C34<>0,0,1) -> 0
B35: رواتب | D35: =C35/90000 -> 0 | E35: =IF(C35<>0,0,1) -> 1
A37: اجمالي المصاريف | C37: =SUM(C13:C35) -> 31200000 | D37: =SUM(D13:D35) -> 346.66667
A38: الرصيد السابق | D38: ='15'!C42 -> 26903.832
A40: الرصيد الحالي | C40: =(C38+C11)-C37 -> -7360000 | D40: =D38 -> 26903.832
B42: الرصيد $ | C42: =D40+(C40/90000) -> 26822.054
A43: ملاحظات
A44: حديد بار + خشب للشومينة
A45: دهان للصالة

Sheet 17
A1: fun park | D1: الصفحة الرئيسية
A3: التاريخ
A5: الايراد | C5: ل ل | D5: $$ | E5: عدد
B6: اراكيل | C6: 6660000 | D6: =C6/90000 -> 74 | E6: 23
B7: مشروبات | C7: 22180000 | D7: =C7/90000 -> 246.44444 | E7: =E11-E6-E8-E9-E10 -> 131
B8: كريب | C8: 5780000 | D8: =C8/90000 -> 64.222222 | E8: 18
B9: العاب | C9: 14500000 | D9: =C9/90000 -> 161.11111 | E9: 67
B10: مختلف | C10: 440000 | D10: =C10/90000 -> 4.8888889 | E10: 3
B11: الاجمالي | C11: =SUM(C6:C10) -> 49560000 | D11: =SUM(D6:D10) -> 550.66667 | E11: 242 | G11: =49560000-C11 -> 0
A12: المصاريف | C12: ل ل | D12: $ | E12: تصفيه
A13: اراكيل | B13: معسل | D13: =C13/90000 -> 0 | E13: =IF(C13<>0,0,1) -> 1
B14: فحم | D14: =C14/90000 -> 0 | E14: =IF(C14<>0,0,1) -> 1
B15: نرابيج و لوازم | D15: =C15/90000 -> 0 | E15: =IF(C15<>0,0,1) -> 1
A16: عصائر | B16: فواكهة | C16: 500000 | D16: =C16/90000 -> 5.5555556 | E16: =IF(C16<>0,0,1) -> 0
B17: عسل | D17: =C17/90000 -> 0 | E17: =IF(C17<>0,0,1) -> 1
B18: نسلة | D18: =C18/90000 -> 0 | E18: =IF(C18<>0,0,1) -> 1
B19: شوكولا | D19: =C19/90000 -> 0 | E19: =IF(C19<>0,0,1) -> 1
B20: حليب | D20: =C20/90000 -> 0 | E20: =IF(C20<>0,0,1) -> 1
B21: مشروبات غازية | D21: =C21/90000 -> 0 | E21: =IF(C21<>0,0,1) -> 1
B22: نيسكافيه و كابتشينو | D22: =C22/90000 -> 0 | E22: =IF(C22<>0,0,1) -> 1
B23: قهوة مكنة | D23: =C23/90000 -> 0 | E23: =IF(C23<>0,0,1) -> 1
B24: لوازم أخرى | D24: =C24/90000 -> 0 | E24: =IF(C24<>0,0,1) -> 1
A25: لوازم | B25: كبيايات | D25: =C25/90000 -> 0 | E25: =IF(C25<>0,0,1) -> 1
B26: محارم | D26: =C26/90000 -> 0 | E26: =IF(C26<>0,0,1) -> 1
B27: مواد تنظيف | D27: =C27/90000 -> 0 | E27: =IF(C27<>0,0,1) -> 1
B28: مختلف | D28: =C28/90000 -> 0 | E28: =IF(C28<>0,0,1) -> 1
B29: مازوت | D29: =C29/90000 -> 0 | E29: =IF(C29<>0,0,1) -> 1
B30: صيانة | D30: =C30/90000 -> 0 | E30: =IF(C30<>0,0,1) -> 1
B31: اقتناء أصول | D31: =C31/90000 -> 0 | E31: =IF(C31<>0,0,1) -> 1
B32: سلف موظفين | D32: =C32/90000 -> 0 | E32: =IF(C32<>0,0,1) -> 1
B33: بنزين | D33: =C33/90000 -> 0 | E33: =IF(C33<>0,0,1) -> 1
B34: نقل | C34: 200000 | D34: =C34/90000 -> 2.2222222 | E34: =IF(C34<>0,0,1) -> 0
B35: رواتب | D35: =C35/90000 -> 0 | E35: =IF(C35<>0,0,1) -> 1
A37: اجمالي المصاريف | C37: =SUM(C13:C35) -> 700000 | D37: =SUM(D13:D35) -> 7.7777778
A38: الرصيد السابق | D38: ='16'!C42 -> 26822.054
A40: الرصيد الحالي | C40: =(C38+C11)-C37 -> 48860000 | D40: =D38 -> 26822.054
B42: الرصيد $ | C42: =D40+(C40/90000) -> 27364.943 | D42: 12370 | E42: =D42-C42 -> -14994.943
A43: ملاحظات

Sheet 18
A1: fun park | D1: الصفحة الرئيسية
A3: التاريخ
A5: الايراد | C5: ل ل | D5: $$ | E5: عدد
B6: اراكيل | C6: 6130000 | D6: =C6/90000 -> 68.111111 | E6: 21
B7: مشروبات | C7: 20250000 | D7: =C7/90000 -> 225 | E7: =E11-E6-E8-E9-E10 -> 110
B8: كريب | C8: 1730000 | D8: =C8/90000 -> 19.222222 | E8: 16
B9: العاب | C9: 8200000 | D9: =C9/90000 -> 91.111111 | E9: 37
B10: مختلف | D10: =C10/90000 -> 0
B11: الاجمالي | C11: =SUM(C6:C10) -> 36310000 | D11: =SUM(D6:D10) -> 403.44444 | E11: 184 | G11: =36310000-C11 -> 0
A12: المصاريف | C12: ل ل | D12: $ | E12: تصفيه
A13: اراكيل | B13: معسل | C13: =53*90000 -> 4770000 | D13: =C13/90000 -> 53 | E13: =IF(C13<>0,0,1) -> 0
B14: فحم | C14: =595*90000 -> 53550000 | D14: =C14/90000 -> 595 | E14: =IF(C14<>0,0,1) -> 0
B15: نرابيج و لوازم | D15: =C15/90000 -> 0 | E15: =IF(C15<>0,0,1) -> 1
A16: عصائر | B16: فواكهة | C16: 1700000 | D16: =C16/90000 -> 18.888889 | E16: =IF(C16<>0,0,1) -> 0
B17: عسل | D17: =C17/90000 -> 0 | E17: =IF(C17<>0,0,1) -> 1
B18: نسلة | D18: =C18/90000 -> 0 | E18: =IF(C18<>0,0,1) -> 1
B19: شوكولا | D19: =C19/90000 -> 0 | E19: =IF(C19<>0,0,1) -> 1
B20: حليب | D20: =C20/90000 -> 0 | E20: =IF(C20<>0,0,1) -> 1
B21: مشروبات غازية | C21: 1800000 | D21: =C21/90000 -> 20 | E21: =IF(C21<>0,0,1) -> 0
B22: نيسكافيه و كابتشينو | D22: =C22/90000 -> 0 | E22: =IF(C22<>0,0,1) -> 1
B23: قهوة مكنة | D23: =C23/90000 -> 0 | E23: =IF(C23<>0,0,1) -> 1
B24: لوازم أخرى | D24: =C24/90000 -> 0 | E24: =IF(C24<>0,0,1) -> 1
A25: لوازم | B25: كبيايات | D25: =C25/90000 -> 0 | E25: =IF(C25<>0,0,1) -> 1
B26: محارم | C26: 270000 | D26: =C26/90000 -> 3 | E26: =IF(C26<>0,0,1) -> 0
B27: مواد تنظيف | C27: 3600000 | D27: =C27/90000 -> 40 | E27: =IF(C27<>0,0,1) -> 0
B28: مختلف | C28: 700000 | D28: =C28/90000 -> 7.7777778 | E28: =IF(C28<>0,0,1) -> 0
B29: مازوت | D29: =C29/90000 -> 0 | E29: =IF(C29<>0,0,1) -> 1
B30: صيانة | D30: =C30/90000 -> 0 | E30: =IF(C30<>0,0,1) -> 1
B31: اقتناء أصول | C31: =75*90000 -> 6750000 | D31: =C31/90000 -> 75 | E31: =IF(C31<>0,0,1) -> 0
B32: سلف موظفين | C32: 2200000 | D32: =C32/90000 -> 24.444444 | E32: =IF(C32<>0,0,1) -> 0
B33: بنزين | D33: =C33/90000 -> 0 | E33: =IF(C33<>0,0,1) -> 1
B34: نقل | C34: 200000 | D34: =C34/90000 -> 2.2222222 | E34: =IF(C34<>0,0,1) -> 0
B35: رواتب | D35: =C35/90000 -> 0 | E35: =IF(C35<>0,0,1) -> 1
A37: اجمالي المصاريف | C37: =SUM(C13:C35) -> 75540000 | D37: =SUM(D13:D35) -> 839.33333
A38: الرصيد السابق | D38: ='17'!C42 -> 27364.943
A40: الرصيد الحالي | C40: =(C38+C11)-C37 -> -39230000 | D40: =D38 -> 27364.943
B42: الرصيد $ | C42: =D40+(C40/90000) -> 26929.054
A43: ملاحظات

Sheet 19
A1: fun park | D1: الصفحة الرئيسية
A3: التاريخ
A5: الايراد | C5: ل ل | D5: $$ | E5: عدد
B6: اراكيل | C6: 5950000 | D6: =C6/90000 -> 66.111111 | E6: 20
B7: مشروبات | C7: 12650000 | D7: =C7/90000 -> 140.55556 | E7: =E11-E6-E8-E9-E10 -> 73
B8: كريب | C8: 4510000 | D8: =C8/90000 -> 50.111111 | E8: 14
B9: العاب | C9: 6550000 | D9: =C9/90000 -> 72.777778 | E9: 31
B10: مختلف | C10: 140000 | D10: =C10/90000 -> 1.5555556 | E10: 1
B11: الاجمالي | C11: =SUM(C6:C10) -> 29800000 | D11: =SUM(D6:D10) -> 331.11111 | E11: 139 | G11: =29800000-C11 -> 0
A12: المصاريف | C12: ل ل | D12: $ | E12: تصفيه
A13: اراكيل | B13: معسل | D13: =C13/90000 -> 0 | E13: =IF(C13<>0,0,1) -> 1
B14: فحم | D14: =C14/90000 -> 0 | E14: =IF(C14<>0,0,1) -> 1
B15: نرابيج و لوازم | D15: =C15/90000 -> 0 | E15: =IF(C15<>0,0,1) -> 1
A16: عصائر | B16: فواكهة | C16: 300000 | D16: =C16/90000 -> 3.3333333 | E16: =IF(C16<>0,0,1) -> 0
B17: عسل | D17: =C17/90000 -> 0 | E17: =IF(C17<>0,0,1) -> 1
B18: نسلة | D18: =C18/90000 -> 0 | E18: =IF(C18<>0,0,1) -> 1
B19: شوكولا | C19: =108*90000 -> 9720000 | D19: =C19/90000 -> 108 | E19: =IF(C19<>0,0,1) -> 0
B20: حليب | D20: =C20/90000 -> 0 | E20: =IF(C20<>0,0,1) -> 1
B21: مشروبات غازية | D21: =C21/90000 -> 0 | E21: =IF(C21<>0,0,1) -> 1
B22: نيسكافيه و كابتشينو | D22: =C22/90000 -> 0 | E22: =IF(C22<>0,0,1) -> 1
B23: قهوة مكنة | D23: =C23/90000 -> 0 | E23: =IF(C23<>0,0,1) -> 1
B24: لوازم أخرى | D24: =C24/90000 -> 0 | E24: =IF(C24<>0,0,1) -> 1
A25: لوازم | B25: كبيايات | D25: =C25/90000 -> 0 | E25: =IF(C25<>0,0,1) -> 1
B26: محارم | D26: =C26/90000 -> 0 | E26: =IF(C26<>0,0,1) -> 1
B27: مواد تنظيف | D27: =C27/90000 -> 0 | E27: =IF(C27<>0,0,1) -> 1
B28: مختلف | D28: =C28/90000 -> 0 | E28: =IF(C28<>0,0,1) -> 1
B29: مازوت | D29: =C29/90000 -> 0 | E29: =IF(C29<>0,0,1) -> 1
B30: صيانة | C30: =223*90000 -> 20070000 | D30: =C30/90000 -> 223 | E30: =IF(C30<>0,0,1) -> 0
B31: اقتناء أصول | D31: =C31/90000 -> 0 | E31: =IF(C31<>0,0,1) -> 1
B32: سلف موظفين | C32: 450000 | D32: =C32/90000 -> 5 | E32: =IF(C32<>0,0,1) -> 0
B33: بنزين | D33: =C33/90000 -> 0 | E33: =IF(C33<>0,0,1) -> 1
B34: نقل | C34: 200000 | D34: =C34/90000 -> 2.2222222 | E34: =IF(C34<>0,0,1) -> 0
B35: رواتب | D35: =C35/90000 -> 0 | E35: =IF(C35<>0,0,1) -> 1
A37: اجمالي المصاريف | C37: =SUM(C13:C35) -> 30740000 | D37: =SUM(D13:D35) -> 341.55556
A38: الرصيد السابق | D38: ='18'!C42 -> 26929.054
A40: الرصيد الحالي | C40: =(C38+C11)-C37 -> -940000 | D40: =D38 -> 26929.054
B42: الرصيد $ | C42: =D40+(C40/90000) -> 26918.61
A43: ملاحظات

Sheet 20
A1: fun park | D1: الصفحة الرئيسية
A3: التاريخ
A5: الايراد | C5: ل ل | D5: $$ | E5: عدد
B6: اراكيل | C6: 1800000 | D6: =C6/90000 -> 20 | E6: 6
B7: مشروبات | C7: 2900000 | D7: =C7/90000 -> 32.222222 | E7: =E11-E6-E8-E9-E10 -> 20
B8: كريب | C8: 320000 | D8: =C8/90000 -> 3.5555556 | E8: 1
B9: العاب | C9: 1050000 | D9: =C9/90000 -> 11.666667 | E9: 6
B10: مختلف | D10: =C10/90000 -> 0
B11: الاجمالي | C11: =SUM(C6:C10) -> 6070000 | D11: =SUM(D6:D10) -> 67.444444 | E11: 33 | G11: =6070000-C11 -> 0
A12: المصاريف | C12: ل ل | D12: $ | E12: تصفيه
A13: اراكيل | B13: معسل | D13: =C13/90000 -> 0 | E13: =IF(C13<>0,0,1) -> 1
B14: فحم | D14: =C14/90000 -> 0 | E14: =IF(C14<>0,0,1) -> 1
B15: نرابيج و لوازم | D15: =C15/90000 -> 0 | E15: =IF(C15<>0,0,1) -> 1
A16: عصائر | B16: فواكهة | C16: 530000 | D16: =C16/90000 -> 5.8888889 | E16: =IF(C16<>0,0,1) -> 0
B17: عسل | C17: 1300000 | D17: =C17/90000 -> 14.444444 | E17: =IF(C17<>0,0,1) -> 0
B18: نسلة | D18: =C18/90000 -> 0 | E18: =IF(C18<>0,0,1) -> 1
B19: شوكولا | D19: =C19/90000 -> 0 | E19: =IF(C19<>0,0,1) -> 1
B20: حليب | D20: =C20/90000 -> 0 | E20: =IF(C20<>0,0,1) -> 1
B21: مشروبات غازية | D21: =C21/90000 -> 0 | E21: =IF(C21<>0,0,1) -> 1
B22: نيسكافيه و كابتشينو | D22: =C22/90000 -> 0 | E22: =IF(C22<>0,0,1) -> 1
B23: قهوة مكنة | C23: =69*90000 -> 6210000 | D23: =C23/90000 -> 69 | E23: =IF(C23<>0,0,1) -> 0
B24: لوازم أخرى | D24: =C24/90000 -> 0 | E24: =IF(C24<>0,0,1) -> 1
A25: لوازم | B25: كبيايات | D25: =C25/90000 -> 0 | E25: =IF(C25<>0,0,1) -> 1
B26: محارم | D26: =C26/90000 -> 0 | E26: =IF(C26<>0,0,1) -> 1
B27: مواد تنظيف | D27: =C27/90000 -> 0 | E27: =IF(C27<>0,0,1) -> 1
B28: مختلف | D28: =C28/90000 -> 0 | E28: =IF(C28<>0,0,1) -> 1
B29: مازوت | D29: =C29/90000 -> 0 | E29: =IF(C29<>0,0,1) -> 1
B30: صيانة | D30: =C30/90000 -> 0 | E30: =IF(C30<>0,0,1) -> 1
B31: اقتناء أصول | D31: =C31/90000 -> 0 | E31: =IF(C31<>0,0,1) -> 1
B32: سلف موظفين | C32: =900000+250000 -> 1150000 | D32: =C32/90000 -> 12.777778 | E32: =IF(C32<>0,0,1) -> 0
B33: بنزين | D33: =C33/90000 -> 0 | E33: =IF(C33<>0,0,1) -> 1
B34: نقل | C34: 200000 | D34: =C34/90000 -> 2.2222222 | E34: =IF(C34<>0,0,1) -> 0
B35: رواتب | D35: =C35/90000 -> 0 | E35: =IF(C35<>0,0,1) -> 1
A37: اجمالي المصاريف | C37: =SUM(C13:C35) -> 9390000 | D37: =SUM(D13:D35) -> 104.33333
A38: الرصيد السابق | D38: ='19'!C42 -> 26918.61
A40: الرصيد الحالي | C40: =(C38+C11)-C37 -> -3320000 | D40: =D38 -> 26918.61
B42: الرصيد $ | C42: =D40+(C40/90000) -> 26881.721
A43: ملاحظات

Sheet 21
A1: fun park | D1: الصفحة الرئيسية
A3: التاريخ
A5: الايراد | C5: ل ل | D5: $$ | E5: عدد
B6: اراكيل | C6: 3200000 | D6: =C6/90000 -> 35.555556 | E6: 11
B7: مشروبات | C7: 10150000 | D7: =C7/90000 -> 112.77778 | E7: =E11-E6-E8-E9-E10 -> 65
B8: كريب | C8: 2060000 | D8: =C8/90000 -> 22.888889 | E8: 6
B9: العاب | C9: 2300000 | D9: =C9/90000 -> 25.555556 | E9: 11
B10: مختلف | C10: 870000 | D10: =C10/90000 -> 9.6666667 | E10: 6
B11: الاجمالي | C11: =SUM(C6:C10) -> 18580000 | D11: =SUM(D6:D10) -> 206.44444 | E11: 99 | G11: =18580000-C11 -> 0
A12: المصاريف | C12: ل ل | D12: $ | E12: تصفيه
A13: اراكيل | B13: معسل | D13: =C13/90000 -> 0 | E13: =IF(C13<>0,0,1) -> 1
B14: فحم | D14: =C14/90000 -> 0 | E14: =IF(C14<>0,0,1) -> 1
B15: نرابيج و لوازم | D15: =C15/90000 -> 0 | E15: =IF(C15<>0,0,1) -> 1
A16: عصائر | B16: فواكهة | D16: =C16/90000 -> 0 | E16: =IF(C16<>0,0,1) -> 1
B17: عسل | D17: =C17/90000 -> 0 | E17: =IF(C17<>0,0,1) -> 1
B18: نسلة | D18: =C18/90000 -> 0 | E18: =IF(C18<>0,0,1) -> 1
B19: شوكولا | C19: 1070000 | D19: =C19/90000 -> 11.888889 | E19: =IF(C19<>0,0,1) -> 0
B20: حليب | D20: =C20/90000 -> 0 | E20: =IF(C20<>0,0,1) -> 1
B21: مشروبات غازية | D21: =C21/90000 -> 0 | E21: =IF(C21<>0,0,1) -> 1
B22: نيسكافيه و كابتشينو | D22: =C22/90000 -> 0 | E22: =IF(C22<>0,0,1) -> 1
B23: قهوة مكنة | D23: =C23/90000 -> 0 | E23: =IF(C23<>0,0,1) -> 1
B24: لوازم أخرى | D24: =C24/90000 -> 0 | E24: =IF(C24<>0,0,1) -> 1
A25: لوازم | B25: كبيايات | D25: =C25/90000 -> 0 | E25: =IF(C25<>0,0,1) -> 1
B26: محارم | D26: =C26/90000 -> 0 | E26: =IF(C26<>0,0,1) -> 1
B27: مواد تنظيف | D27: =C27/90000 -> 0 | E27: =IF(C27<>0,0,1) -> 1
B28: مختلف | D28: =C28/90000 -> 0 | E28: =IF(C28<>0,0,1) -> 1
B29: مازوت | D29: =C29/90000 -> 0 | E29: =IF(C29<>0,0,1) -> 1
B30: صيانة | C30: 450000 | D30: =C30/90000 -> 5 | E30: =IF(C30<>0,0,1) -> 0
B31: اقتناء أصول | D31: =C31/90000 -> 0 | E31: =IF(C31<>0,0,1) -> 1
B32: سلف موظفين | C32: 2100000 | D32: =C32/90000 -> 23.333333 | E32: =IF(C32<>0,0,1) -> 0
B33: بنزين | D33: =C33/90000 -> 0 | E33: =IF(C33<>0,0,1) -> 1
B34: نقل | C34: 200000 | D34: =C34/90000 -> 2.2222222 | E34: =IF(C34<>0,0,1) -> 0
B35: رواتب | D35: =C35/90000 -> 0 | E35: =IF(C35<>0,0,1) -> 1
A37: اجمالي المصاريف | C37: =SUM(C13:C35) -> 3820000 | D37: =SUM(D13:D35) -> 42.444444
A38: الرصيد السابق | D38: ='20'!C42 -> 26881.721
A40: الرصيد الحالي | C40: =(C38+C11)-C37 -> 14760000 | D40: =D38 -> 26881.721
B42: الرصيد $ | C42: =D40+(C40/90000) -> 27045.721
A43: ملاحظات

Sheet 22
A1: fun park | D1: الصفحة الرئيسية
A3: التاريخ
A5: الايراد | C5: ل ل | D5: $$ | E5: عدد
B6: اراكيل | C6: 4110000 | D6: =C6/90000 -> 45.666667 | E6: 14
B7: مشروبات | C7: 10100000 | D7: =C7/90000 -> 112.22222 | E7: =E11-E6-E8-E9-E10 -> 58
B8: كريب | C8: 1270000 | D8: =C8/90000 -> 14.111111 | E8: 4
B9: العاب | C9: 1500000 | D9: =C9/90000 -> 16.666667 | E9: 6
B10: مختلف | D10: =C10/90000 -> 0
B11: الاجمالي | C11: =SUM(C6:C10) -> 16980000 | D11: =SUM(D6:D10) -> 188.66667 | E11: 82 | G11: =16980000-C11 -> 0
A12: المصاريف | C12: ل ل | D12: $ | E12: تصفيه
A13: اراكيل | B13: معسل | D13: =C13/90000 -> 0 | E13: =IF(C13<>0,0,1) -> 1
B14: فحم | D14: =C14/90000 -> 0 | E14: =IF(C14<>0,0,1) -> 1
B15: نرابيج و لوازم | D15: =C15/90000 -> 0 | E15: =IF(C15<>0,0,1) -> 1
A16: عصائر | B16: فواكهة | D16: =C16/90000 -> 0 | E16: =IF(C16<>0,0,1) -> 1
B17: عسل | D17: =C17/90000 -> 0 | E17: =IF(C17<>0,0,1) -> 1
B18: نسلة | D18: =C18/90000 -> 0 | E18: =IF(C18<>0,0,1) -> 1
B19: شوكولا | D19: =C19/90000 -> 0 | E19: =IF(C19<>0,0,1) -> 1
B20: حليب | D20: =C20/90000 -> 0 | E20: =IF(C20<>0,0,1) -> 1
B21: مشروبات غازية | D21: =C21/90000 -> 0 | E21: =IF(C21<>0,0,1) -> 1
B22: نيسكافيه و كابتشينو | D22: =C22/90000 -> 0 | E22: =IF(C22<>0,0,1) -> 1
B23: قهوة مكنة | D23: =C23/90000 -> 0 | E23: =IF(C23<>0,0,1) -> 1
B24: لوازم أخرى | D24: =C24/90000 -> 0 | E24: =IF(C24<>0,0,1) -> 1
A25: لوازم | B25: كبيايات | D25: =C25/90000 -> 0 | E25: =IF(C25<>0,0,1) -> 1
B26: محارم | D26: =C26/90000 -> 0 | E26: =IF(C26<>0,0,1) -> 1
B27: مواد تنظيف | D27: =C27/90000 -> 0 | E27: =IF(C27<>0,0,1) -> 1
B28: مختلف | D28: =C28/90000 -> 0 | E28: =IF(C28<>0,0,1) -> 1
B29: مازوت | D29: =C29/90000 -> 0 | E29: =IF(C29<>0,0,1) -> 1
B30: صيانة | D30: =C30/90000 -> 0 | E30: =IF(C30<>0,0,1) -> 1
B31: اقتناء أصول | C31: =270*90000 -> 24300000 | D31: =C31/90000 -> 270 | E31: =IF(C31<>0,0,1) -> 0
B32: سلف موظفين | C32: 400000 | D32: =C32/90000 -> 4.4444444 | E32: =IF(C32<>0,0,1) -> 0
B33: بنزين | D33: =C33/90000 -> 0 | E33: =IF(C33<>0,0,1) -> 1
B34: نقل | C34: 200000 | D34: =C34/90000 -> 2.2222222 | E34: =IF(C34<>0,0,1) -> 0
B35: رواتب | D35: =C35/90000 -> 0 | E35: =IF(C35<>0,0,1) -> 1
A37: اجمالي المصاريف | C37: =SUM(C13:C35) -> 24900000 | D37: =SUM(D13:D35) -> 276.66667
A38: الرصيد السابق | D38: ='21'!C42 -> 27045.721
A40: الرصيد الحالي | C40: =(C38+C11)-C37 -> -7920000 | D40: =D38 -> 27045.721
B42: الرصيد $ | C42: =D40+(C40/90000) -> 26957.721
A43: ملاحظات

Sheet 23
A1: fun park | D1: الصفحة الرئيسية
A3: التاريخ
A5: الايراد | C5: ل ل | D5: $$ | E5: عدد
B6: اراكيل | C6: 3040000 | D6: =C6/90000 -> 33.777778 | E6: 10
B7: مشروبات | C7: 7210000 | D7: =C7/90000 -> 80.111111 | E7: =E11-E6-E8-E9-E10 -> 36
B8: كريب | C8: 3920000 | D8: =C8/90000 -> 43.555556 | E8: 12
B9: العاب | C9: 2750000 | D9: =C9/90000 -> 30.555556 | E9: 14
B10: مختلف | C10: 300000 | D10: =C10/90000 -> 3.3333333 | E10: 2
B11: الاجمالي | C11: =SUM(C6:C10) -> 17220000 | D11: =SUM(D6:D10) -> 191.33333 | E11: 74 | G11: =17220000-C11 -> 0
A12: المصاريف | C12: ل ل | D12: $ | E12: تصفيه
A13: اراكيل | B13: معسل | D13: =C13/90000 -> 0 | E13: =IF(C13<>0,0,1) -> 1
B14: فحم | D14: =C14/90000 -> 0 | E14: =IF(C14<>0,0,1) -> 1
B15: نرابيج و لوازم | C15: 1800000 | D15: =C15/90000 -> 20 | E15: =IF(C15<>0,0,1) -> 0
A16: عصائر | B16: فواكهة | C16: 1000000 | D16: =C16/90000 -> 11.111111 | E16: =IF(C16<>0,0,1) -> 0
B17: عسل | D17: =C17/90000 -> 0 | E17: =IF(C17<>0,0,1) -> 1
B18: نسلة | D18: =C18/90000 -> 0 | E18: =IF(C18<>0,0,1) -> 1
B19: شوكولا | D19: =C19/90000 -> 0 | E19: =IF(C19<>0,0,1) -> 1
B20: حليب | D20: =C20/90000 -> 0 | E20: =IF(C20<>0,0,1) -> 1
B21: مشروبات غازية | D21: =C21/90000 -> 0 | E21: =IF(C21<>0,0,1) -> 1
B22: نيسكافيه و كابتشينو | D22: =C22/90000 -> 0 | E22: =IF(C22<>0,0,1) -> 1
B23: قهوة مكنة | D23: =C23/90000 -> 0 | E23: =IF(C23<>0,0,1) -> 1
B24: لوازم أخرى | C24: 1899999 | D24: =C24/90000 -> 21.1111 | E24: =IF(C24<>0,0,1) -> 0
A25: لوازم | B25: كبيايات | D25: =C25/90000 -> 0 | E25: =IF(C25<>0,0,1) -> 1
B26: محارم | D26: =C26/90000 -> 0 | E26: =IF(C26<>0,0,1) -> 1
B27: مواد تنظيف | D27: =C27/90000 -> 0 | E27: =IF(C27<>0,0,1) -> 1
B28: مختلف | C28: 50000 | D28: =C28/90000 -> 0.55555556 | E28: =IF(C28<>0,0,1) -> 0
B29: مازوت | D29: =C29/90000 -> 0 | E29: =IF(C29<>0,0,1) -> 1
B30: صيانة | C30: =70*90000 -> 6300000 | D30: =C30/90000 -> 70 | E30: =IF(C30<>0,0,1) -> 0
B31: اقتناء أصول | D31: =C31/90000 -> 0 | E31: =IF(C31<>0,0,1) -> 1
B32: سلف موظفين | C32: 400000 | D32: =C32/90000 -> 4.4444444 | E32: =IF(C32<>0,0,1) -> 0
B33: بنزين | D33: =C33/90000 -> 0 | E33: =IF(C33<>0,0,1) -> 1
B34: نقل | C34: 200000 | D34: =C34/90000 -> 2.2222222 | E34: =IF(C34<>0,0,1) -> 0
B35: رواتب | D35: =C35/90000 -> 0 | E35: =IF(C35<>0,0,1) -> 1
A37: اجمالي المصاريف | C37: =SUM(C13:C35) -> 11649999 | D37: =SUM(D13:D35) -> 129.44443
A38: الرصيد السابق | D38: ='22'!C42 -> 26957.721
A40: الرصيد الحالي | C40: =(C38+C11)-C37 -> 5570001 | D40: =D38 -> 26957.721
B42: الرصيد $ | C42: =D40+(C40/90000) -> 27019.61
A43: ملاحظات
A44: صيانة بسكلاتات

Sheet 24
A1: fun park | D1: الصفحة الرئيسية
